[2025-05-08 10:18:33,757.757] _internal.py -> _log line:97 [INFO]: [31m[1mWARNING: This is a development server. Do not use it in a production deployment. Use a production WSGI server instead.[0m
 * Running on http://127.0.0.1:5000
[2025-05-08 10:18:33,758.758] _internal.py -> _log line:97 [INFO]: [33mPress CTRL+C to quit[0m
[2025-05-08 10:18:33,764.764] _internal.py -> _log line:97 [INFO]:  * Restarting with stat
[2025-05-08 10:19:02,926.926] _internal.py -> _log line:97 [WARNING]:  * Debugger is active!
[2025-05-08 10:19:02,964.964] _internal.py -> _log line:97 [INFO]:  * Debugger PIN: 674-688-502
[2025-05-08 10:19:57,499.499] _internal.py -> _log line:97 [INFO]: 127.0.0.1 - - [08/May/2025 10:19:57] "GET /ping HTTP/1.1" 200 -
[2025-05-08 10:25:01,641.641] _internal.py -> _log line:97 [INFO]: [31m[1mWARNING: This is a development server. Do not use it in a production deployment. Use a production WSGI server instead.[0m
 * Running on http://127.0.0.1:5000
[2025-05-08 10:25:01,642.642] _internal.py -> _log line:97 [INFO]: [33mPress CTRL+C to quit[0m
[2025-05-08 10:25:01,648.648] _internal.py -> _log line:97 [INFO]:  * Restarting with stat
[2025-05-08 10:25:24,196.196] _internal.py -> _log line:97 [WARNING]:  * Debugger is active!
[2025-05-08 10:25:24,213.213] _internal.py -> _log line:97 [INFO]:  * Debugger PIN: 674-688-502
[2025-05-08 10:26:15,370.370] _internal.py -> _log line:97 [INFO]: 127.0.0.1 - - [08/May/2025 10:26:15] "GET /ping HTTP/1.1" 200 -
[2025-05-08 10:27:00,467.467] _internal.py -> _log line:97 [INFO]:  * Detected change in 'C:\\Users\\Lenovo\\Desktop\\llmops-api\\internal\\service\\conversation_service.py', reloading
[2025-05-08 10:27:01,943.943] _internal.py -> _log line:97 [INFO]:  * Restarting with stat
[2025-05-08 10:27:29,819.819] _internal.py -> _log line:97 [WARNING]:  * Debugger is active!
[2025-05-08 10:27:29,831.831] _internal.py -> _log line:97 [INFO]:  * Debugger PIN: 674-688-502
[2025-05-08 10:27:37,147.147] _internal.py -> _log line:97 [INFO]: 127.0.0.1 - - [08/May/2025 10:27:37] "GET /ping HTTP/1.1" 200 -
[2025-05-08 10:56:19,683.683] _internal.py -> _log line:97 [INFO]: [31m[1mWARNING: This is a development server. Do not use it in a production deployment. Use a production WSGI server instead.[0m
 * Running on http://127.0.0.1:5000
[2025-05-08 10:56:19,683.683] _internal.py -> _log line:97 [INFO]: [33mPress CTRL+C to quit[0m
[2025-05-08 10:56:19,687.687] _internal.py -> _log line:97 [INFO]:  * Restarting with stat
[2025-05-08 10:56:42,762.762] _internal.py -> _log line:97 [WARNING]:  * Debugger is active!
[2025-05-08 10:56:42,779.779] _internal.py -> _log line:97 [INFO]:  * Debugger PIN: 674-688-502
[2025-05-08 11:01:35,795.795] _internal.py -> _log line:97 [INFO]:  * Detected change in 'C:\\Users\\Lenovo\\Desktop\\llmops-api\\internal\\service\\conversation_service.py', reloading
[2025-05-08 11:01:37,365.365] _internal.py -> _log line:97 [INFO]:  * Restarting with stat
[2025-05-08 11:01:59,457.457] _internal.py -> _log line:97 [WARNING]:  * Debugger is active!
[2025-05-08 11:01:59,472.472] _internal.py -> _log line:97 [INFO]:  * Debugger PIN: 674-688-502
[2025-05-08 11:02:48,976.976] _internal.py -> _log line:97 [INFO]:  * Detected change in 'C:\\Users\\Lenovo\\Desktop\\llmops-api\\internal\\service\\conversation_service.py', reloading
[2025-05-08 11:02:50,709.709] _internal.py -> _log line:97 [INFO]:  * Restarting with stat
[2025-05-08 11:03:13,004.004] _internal.py -> _log line:97 [WARNING]:  * Debugger is active!
[2025-05-08 11:03:13,016.016] _internal.py -> _log line:97 [INFO]:  * Debugger PIN: 674-688-502
[2025-05-08 11:03:14,801.801] http.py -> _register_error_handler line:54 [ERROR]: An error occurred: Error code: 400 - {'error': {'message': 'Model Not Exist', 'type': 'invalid_request_error', 'param': None, 'code': 'invalid_request_error'}}
Traceback (most recent call last):
  File "C:\Users\Lenovo\Desktop\llmops-api\venv\lib\site-packages\flask\app.py", line 870, in full_dispatch_request
    rv = self.dispatch_request()
  File "C:\Users\Lenovo\Desktop\llmops-api\venv\lib\site-packages\flask\app.py", line 855, in dispatch_request
    return self.ensure_sync(self.view_functions[rule.endpoint])(**view_args)  # type: ignore[no-any-return]
  File "C:\Users\Lenovo\Desktop\llmops-api\internal\handler\app_handler.py", line 265, in ping
    questions = self.conversation_service.generate_suggested_questions(human_message)
  File "C:\Users\Lenovo\Desktop\llmops-api\internal\service\conversation_service.py", line 96, in generate_suggested_questions
    suggested_questions = chain.invoke({"histories": histories})
  File "C:\Users\Lenovo\Desktop\llmops-api\venv\lib\site-packages\langchain_core\runnables\base.py", line 3025, in invoke
    input = context.run(step.invoke, input, config)
  File "C:\Users\Lenovo\Desktop\llmops-api\venv\lib\site-packages\langchain_core\runnables\base.py", line 5358, in invoke
    return self.bound.invoke(
  File "C:\Users\Lenovo\Desktop\llmops-api\venv\lib\site-packages\langchain_core\language_models\chat_models.py", line 307, in invoke
    self.generate_prompt(
  File "C:\Users\Lenovo\Desktop\llmops-api\venv\lib\site-packages\langchain_core\language_models\chat_models.py", line 843, in generate_prompt
    return self.generate(prompt_messages, stop=stop, callbacks=callbacks, **kwargs)
  File "C:\Users\Lenovo\Desktop\llmops-api\venv\lib\site-packages\langchain_core\language_models\chat_models.py", line 683, in generate
    self._generate_with_cache(
  File "C:\Users\Lenovo\Desktop\llmops-api\venv\lib\site-packages\langchain_core\language_models\chat_models.py", line 908, in _generate_with_cache
    result = self._generate(
  File "C:\Users\Lenovo\Desktop\llmops-api\venv\lib\site-packages\langchain_openai\chat_models\base.py", line 925, in _generate
    response = self.client.create(**payload)
  File "C:\Users\Lenovo\Desktop\llmops-api\venv\lib\site-packages\openai\_utils\_utils.py", line 279, in wrapper
    return func(*args, **kwargs)
  File "C:\Users\Lenovo\Desktop\llmops-api\venv\lib\site-packages\openai\resources\chat\completions\completions.py", line 914, in create
    return self._post(
  File "C:\Users\Lenovo\Desktop\llmops-api\venv\lib\site-packages\openai\_base_client.py", line 1242, in post
    return cast(ResponseT, self.request(cast_to, opts, stream=stream, stream_cls=stream_cls))
  File "C:\Users\Lenovo\Desktop\llmops-api\venv\lib\site-packages\openai\_base_client.py", line 919, in request
    return self._request(
  File "C:\Users\Lenovo\Desktop\llmops-api\venv\lib\site-packages\openai\_base_client.py", line 1023, in _request
    raise self._make_status_error_from_response(err.response) from None
openai.BadRequestError: Error code: 400 - {'error': {'message': 'Model Not Exist', 'type': 'invalid_request_error', 'param': None, 'code': 'invalid_request_error'}}
[2025-05-08 11:03:14,830.830] _internal.py -> _log line:97 [INFO]: 127.0.0.1 - - [08/May/2025 11:03:14] "[35m[1mGET /ping HTTP/1.1[0m" 500 -
[2025-05-08 11:03:21,641.641] _internal.py -> _log line:97 [INFO]:  * Detected change in 'C:\\Users\\Lenovo\\Desktop\\llmops-api\\internal\\service\\conversation_service.py', reloading
[2025-05-08 11:03:23,343.343] _internal.py -> _log line:97 [INFO]:  * Restarting with stat
[2025-05-08 11:03:42,962.962] _internal.py -> _log line:97 [WARNING]:  * Debugger is active!
[2025-05-08 11:03:42,974.974] _internal.py -> _log line:97 [INFO]:  * Debugger PIN: 674-688-502
[2025-05-08 11:03:51,067.067] _internal.py -> _log line:97 [INFO]: 127.0.0.1 - - [08/May/2025 11:03:51] "GET /ping HTTP/1.1" 200 -
[2025-05-08 12:09:22,422.422] _internal.py -> _log line:97 [INFO]: [31m[1mWARNING: This is a development server. Do not use it in a production deployment. Use a production WSGI server instead.[0m
 * Running on http://127.0.0.1:5000
[2025-05-08 12:09:22,423.423] _internal.py -> _log line:97 [INFO]: [33mPress CTRL+C to quit[0m
[2025-05-08 12:09:22,427.427] _internal.py -> _log line:97 [INFO]:  * Restarting with stat
[2025-05-08 12:09:48,554.554] _internal.py -> _log line:97 [WARNING]:  * Debugger is active!
[2025-05-08 12:09:48,567.567] _internal.py -> _log line:97 [INFO]:  * Debugger PIN: 674-688-502
[2025-05-08 21:21:49,743.743] _internal.py -> _log line:97 [INFO]: [31m[1mWARNING: This is a development server. Do not use it in a production deployment. Use a production WSGI server instead.[0m
 * Running on http://127.0.0.1:5000
[2025-05-08 21:21:49,744.744] _internal.py -> _log line:97 [INFO]: [33mPress CTRL+C to quit[0m
[2025-05-08 21:21:49,748.748] _internal.py -> _log line:97 [INFO]:  * Restarting with stat
[2025-05-08 21:22:17,433.433] _internal.py -> _log line:97 [WARNING]:  * Debugger is active!
[2025-05-08 21:22:17,452.452] _internal.py -> _log line:97 [INFO]:  * Debugger PIN: 674-688-502
[2025-05-08 21:24:33,300.300] _internal.py -> _log line:97 [INFO]:  * Detected change in 'C:\\Users\\Lenovo\\Desktop\\llmops-api\\internal\\core\\agent\\entities\\agent_entity.py', reloading
[2025-05-08 21:24:34,783.783] _internal.py -> _log line:97 [INFO]:  * Restarting with stat
[2025-05-08 21:24:57,506.506] _internal.py -> _log line:97 [WARNING]:  * Debugger is active!
[2025-05-08 21:24:57,520.520] _internal.py -> _log line:97 [INFO]:  * Debugger PIN: 674-688-502
[2025-05-08 21:25:25,596.596] http.py -> _register_error_handler line:54 [ERROR]: An error occurred: no validator found for <class 'langchain_core.language_models.base.BaseLanguageModel'>, see `arbitrary_types_allowed` in Config
Traceback (most recent call last):
  File "C:\Users\Lenovo\Desktop\llmops-api\venv\lib\site-packages\flask\app.py", line 870, in full_dispatch_request
    rv = self.dispatch_request()
  File "C:\Users\Lenovo\Desktop\llmops-api\venv\lib\site-packages\flask\app.py", line 855, in dispatch_request
    return self.ensure_sync(self.view_functions[rule.endpoint])(**view_args)  # type: ignore[no-any-return]
  File "C:\Users\Lenovo\Desktop\llmops-api\internal\handler\app_handler.py", line 260, in ping
    from internal.core.agent.agents import FunctionCallAgent
  File "C:\Users\Lenovo\Desktop\llmops-api\internal\core\agent\agents\__init__.py", line 1, in <module>
    from .base_agent import BaseAgent
  File "C:\Users\Lenovo\Desktop\llmops-api\internal\core\agent\agents\base_agent.py", line 2, in <module>
    from internal.core.agent.entities.agent_entity import AgentConfig
  File "C:\Users\Lenovo\Desktop\llmops-api\internal\core\agent\entities\agent_entity.py", line 33, in <module>
    class AgentConfig(BaseModel):
  File "C:\Users\Lenovo\Desktop\llmops-api\venv\lib\site-packages\pydantic\v1\main.py", line 197, in __new__
    fields[ann_name] = ModelField.infer(
  File "C:\Users\Lenovo\Desktop\llmops-api\venv\lib\site-packages\pydantic\v1\fields.py", line 504, in infer
    return cls(
  File "C:\Users\Lenovo\Desktop\llmops-api\venv\lib\site-packages\pydantic\v1\fields.py", line 434, in __init__
    self.prepare()
  File "C:\Users\Lenovo\Desktop\llmops-api\venv\lib\site-packages\pydantic\v1\fields.py", line 555, in prepare
    self.populate_validators()
  File "C:\Users\Lenovo\Desktop\llmops-api\venv\lib\site-packages\pydantic\v1\fields.py", line 829, in populate_validators
    *(get_validators() if get_validators else list(find_validators(self.type_, self.model_config))),
  File "C:\Users\Lenovo\Desktop\llmops-api\venv\lib\site-packages\pydantic\v1\validators.py", line 768, in find_validators
    raise RuntimeError(f'no validator found for {type_}, see `arbitrary_types_allowed` in Config')
RuntimeError: no validator found for <class 'langchain_core.language_models.base.BaseLanguageModel'>, see `arbitrary_types_allowed` in Config
[2025-05-08 21:25:25,622.622] _internal.py -> _log line:97 [INFO]: 127.0.0.1 - - [08/May/2025 21:25:25] "[35m[1mGET /ping HTTP/1.1[0m" 500 -
[2025-05-08 21:26:05,251.251] http.py -> _register_error_handler line:54 [ERROR]: An error occurred: no validator found for <class 'langchain_core.language_models.base.BaseLanguageModel'>, see `arbitrary_types_allowed` in Config
Traceback (most recent call last):
  File "C:\Users\Lenovo\Desktop\llmops-api\venv\lib\site-packages\flask\app.py", line 870, in full_dispatch_request
    rv = self.dispatch_request()
  File "C:\Users\Lenovo\Desktop\llmops-api\venv\lib\site-packages\flask\app.py", line 855, in dispatch_request
    return self.ensure_sync(self.view_functions[rule.endpoint])(**view_args)  # type: ignore[no-any-return]
  File "C:\Users\Lenovo\Desktop\llmops-api\internal\handler\app_handler.py", line 260, in ping
    from internal.core.agent.agents import FunctionCallAgent
  File "C:\Users\Lenovo\Desktop\llmops-api\internal\core\agent\agents\__init__.py", line 1, in <module>
    from .base_agent import BaseAgent
  File "C:\Users\Lenovo\Desktop\llmops-api\internal\core\agent\agents\base_agent.py", line 2, in <module>
    from internal.core.agent.entities.agent_entity import AgentConfig
  File "C:\Users\Lenovo\Desktop\llmops-api\internal\core\agent\entities\agent_entity.py", line 33, in <module>
    class AgentConfig(BaseModel):
  File "C:\Users\Lenovo\Desktop\llmops-api\venv\lib\site-packages\pydantic\v1\main.py", line 197, in __new__
    fields[ann_name] = ModelField.infer(
  File "C:\Users\Lenovo\Desktop\llmops-api\venv\lib\site-packages\pydantic\v1\fields.py", line 504, in infer
    return cls(
  File "C:\Users\Lenovo\Desktop\llmops-api\venv\lib\site-packages\pydantic\v1\fields.py", line 434, in __init__
    self.prepare()
  File "C:\Users\Lenovo\Desktop\llmops-api\venv\lib\site-packages\pydantic\v1\fields.py", line 555, in prepare
    self.populate_validators()
  File "C:\Users\Lenovo\Desktop\llmops-api\venv\lib\site-packages\pydantic\v1\fields.py", line 829, in populate_validators
    *(get_validators() if get_validators else list(find_validators(self.type_, self.model_config))),
  File "C:\Users\Lenovo\Desktop\llmops-api\venv\lib\site-packages\pydantic\v1\validators.py", line 768, in find_validators
    raise RuntimeError(f'no validator found for {type_}, see `arbitrary_types_allowed` in Config')
RuntimeError: no validator found for <class 'langchain_core.language_models.base.BaseLanguageModel'>, see `arbitrary_types_allowed` in Config
[2025-05-08 21:26:05,272.272] _internal.py -> _log line:97 [INFO]: 127.0.0.1 - - [08/May/2025 21:26:05] "[35m[1mGET /ping HTTP/1.1[0m" 500 -
[2025-05-08 21:29:43,280.280] _internal.py -> _log line:97 [INFO]:  * Detected change in 'C:\\Users\\Lenovo\\Desktop\\llmops-api\\internal\\core\\agent\\entities\\agent_entity.py', reloading
[2025-05-08 21:29:45,442.442] _internal.py -> _log line:97 [INFO]:  * Restarting with stat
[2025-05-08 21:30:10,866.866] _internal.py -> _log line:97 [WARNING]:  * Debugger is active!
[2025-05-08 21:30:10,882.882] _internal.py -> _log line:97 [INFO]:  * Debugger PIN: 674-688-502
[2025-05-08 21:30:13,139.139] http.py -> _register_error_handler line:54 [ERROR]: An error occurred: no validator found for <class 'langchain_core.language_models.base.BaseLanguageModel'>, see `arbitrary_types_allowed` in Config
Traceback (most recent call last):
  File "C:\Users\Lenovo\Desktop\llmops-api\venv\lib\site-packages\flask\app.py", line 870, in full_dispatch_request
    rv = self.dispatch_request()
  File "C:\Users\Lenovo\Desktop\llmops-api\venv\lib\site-packages\flask\app.py", line 855, in dispatch_request
    return self.ensure_sync(self.view_functions[rule.endpoint])(**view_args)  # type: ignore[no-any-return]
  File "C:\Users\Lenovo\Desktop\llmops-api\internal\handler\app_handler.py", line 260, in ping
    from internal.core.agent.agents import FunctionCallAgent
  File "C:\Users\Lenovo\Desktop\llmops-api\internal\core\agent\agents\__init__.py", line 1, in <module>
    from .base_agent import BaseAgent
  File "C:\Users\Lenovo\Desktop\llmops-api\internal\core\agent\agents\base_agent.py", line 2, in <module>
    from internal.core.agent.entities.agent_entity import AgentConfig
  File "C:\Users\Lenovo\Desktop\llmops-api\internal\core\agent\entities\agent_entity.py", line 35, in <module>
    class AgentConfig(BaseModel):
  File "C:\Users\Lenovo\Desktop\llmops-api\venv\lib\site-packages\pydantic\v1\main.py", line 197, in __new__
    fields[ann_name] = ModelField.infer(
  File "C:\Users\Lenovo\Desktop\llmops-api\venv\lib\site-packages\pydantic\v1\fields.py", line 504, in infer
    return cls(
  File "C:\Users\Lenovo\Desktop\llmops-api\venv\lib\site-packages\pydantic\v1\fields.py", line 434, in __init__
    self.prepare()
  File "C:\Users\Lenovo\Desktop\llmops-api\venv\lib\site-packages\pydantic\v1\fields.py", line 555, in prepare
    self.populate_validators()
  File "C:\Users\Lenovo\Desktop\llmops-api\venv\lib\site-packages\pydantic\v1\fields.py", line 829, in populate_validators
    *(get_validators() if get_validators else list(find_validators(self.type_, self.model_config))),
  File "C:\Users\Lenovo\Desktop\llmops-api\venv\lib\site-packages\pydantic\v1\validators.py", line 768, in find_validators
    raise RuntimeError(f'no validator found for {type_}, see `arbitrary_types_allowed` in Config')
RuntimeError: no validator found for <class 'langchain_core.language_models.base.BaseLanguageModel'>, see `arbitrary_types_allowed` in Config
[2025-05-08 21:30:13,190.190] _internal.py -> _log line:97 [INFO]: 127.0.0.1 - - [08/May/2025 21:30:13] "[35m[1mGET /ping HTTP/1.1[0m" 500 -
[2025-05-08 21:32:17,549.549] _internal.py -> _log line:97 [INFO]:  * Detected change in 'C:\\Users\\Lenovo\\Desktop\\llmops-api\\internal\\core\\agent\\agents\\base_agent.py', reloading
[2025-05-08 21:32:19,113.113] _internal.py -> _log line:97 [INFO]:  * Restarting with stat
[2025-05-08 21:32:48,920.920] _internal.py -> _log line:97 [WARNING]:  * Debugger is active!
[2025-05-08 21:32:48,934.934] _internal.py -> _log line:97 [INFO]:  * Debugger PIN: 674-688-502
[2025-05-08 21:32:50,602.602] http.py -> _register_error_handler line:54 [ERROR]: An error occurred: no validator found for <class 'langchain_core.language_models.base.BaseLanguageModel'>, see `arbitrary_types_allowed` in Config
Traceback (most recent call last):
  File "C:\Users\Lenovo\Desktop\llmops-api\venv\lib\site-packages\flask\app.py", line 870, in full_dispatch_request
    rv = self.dispatch_request()
  File "C:\Users\Lenovo\Desktop\llmops-api\venv\lib\site-packages\flask\app.py", line 855, in dispatch_request
    return self.ensure_sync(self.view_functions[rule.endpoint])(**view_args)  # type: ignore[no-any-return]
  File "C:\Users\Lenovo\Desktop\llmops-api\internal\handler\app_handler.py", line 260, in ping
    from internal.core.agent.agents import FunctionCallAgent
  File "C:\Users\Lenovo\Desktop\llmops-api\internal\core\agent\agents\__init__.py", line 1, in <module>
    from .base_agent import BaseAgent
  File "C:\Users\Lenovo\Desktop\llmops-api\internal\core\agent\agents\base_agent.py", line 2, in <module>
    from internal.core.agent.entities.agent_entity import AgentConfig
  File "C:\Users\Lenovo\Desktop\llmops-api\internal\core\agent\entities\agent_entity.py", line 35, in <module>
    class AgentConfig(BaseModel):
  File "C:\Users\Lenovo\Desktop\llmops-api\venv\lib\site-packages\pydantic\v1\main.py", line 197, in __new__
    fields[ann_name] = ModelField.infer(
  File "C:\Users\Lenovo\Desktop\llmops-api\venv\lib\site-packages\pydantic\v1\fields.py", line 504, in infer
    return cls(
  File "C:\Users\Lenovo\Desktop\llmops-api\venv\lib\site-packages\pydantic\v1\fields.py", line 434, in __init__
    self.prepare()
  File "C:\Users\Lenovo\Desktop\llmops-api\venv\lib\site-packages\pydantic\v1\fields.py", line 555, in prepare
    self.populate_validators()
  File "C:\Users\Lenovo\Desktop\llmops-api\venv\lib\site-packages\pydantic\v1\fields.py", line 829, in populate_validators
    *(get_validators() if get_validators else list(find_validators(self.type_, self.model_config))),
  File "C:\Users\Lenovo\Desktop\llmops-api\venv\lib\site-packages\pydantic\v1\validators.py", line 768, in find_validators
    raise RuntimeError(f'no validator found for {type_}, see `arbitrary_types_allowed` in Config')
RuntimeError: no validator found for <class 'langchain_core.language_models.base.BaseLanguageModel'>, see `arbitrary_types_allowed` in Config
[2025-05-08 21:32:50,632.632] _internal.py -> _log line:97 [INFO]: 127.0.0.1 - - [08/May/2025 21:32:50] "[35m[1mGET /ping HTTP/1.1[0m" 500 -
[2025-05-08 21:34:30,632.632] _internal.py -> _log line:97 [INFO]:  * Detected change in 'C:\\Users\\Lenovo\\Desktop\\llmops-api\\internal\\core\\agent\\entities\\agent_entity.py', reloading
[2025-05-08 21:34:32,225.225] _internal.py -> _log line:97 [INFO]:  * Restarting with stat
[2025-05-08 21:35:24,814.814] _internal.py -> _log line:97 [INFO]: [31m[1mWARNING: This is a development server. Do not use it in a production deployment. Use a production WSGI server instead.[0m
 * Running on http://127.0.0.1:5000
[2025-05-08 21:35:24,815.815] _internal.py -> _log line:97 [INFO]: [33mPress CTRL+C to quit[0m
[2025-05-08 21:35:24,817.817] _internal.py -> _log line:97 [INFO]:  * Restarting with stat
[2025-05-08 21:35:49,218.218] _internal.py -> _log line:97 [WARNING]:  * Debugger is active!
[2025-05-08 21:35:49,233.233] _internal.py -> _log line:97 [INFO]:  * Debugger PIN: 674-688-502
[2025-05-08 21:35:55,147.147] _internal.py -> _log line:97 [INFO]: 127.0.0.1 - - [08/May/2025 21:35:55] "GET /ping HTTP/1.1" 200 -
[2025-05-08 21:37:27,239.239] _internal.py -> _log line:97 [INFO]:  * Detected change in 'C:\\Users\\Lenovo\\Desktop\\llmops-api\\internal\\handler\\app_handler.py', reloading
[2025-05-08 21:37:28,631.631] _internal.py -> _log line:97 [INFO]:  * Restarting with stat
[2025-05-08 21:37:54,078.078] _internal.py -> _log line:97 [WARNING]:  * Debugger is active!
[2025-05-08 21:37:54,096.096] _internal.py -> _log line:97 [INFO]:  * Debugger PIN: 674-688-502
[2025-05-08 21:37:56,084.084] http.py -> _register_error_handler line:54 [ERROR]: An error occurred: no validator found for <class 'langchain_core.language_models.base.BaseLanguageModel'>, see `arbitrary_types_allowed` in Config
Traceback (most recent call last):
  File "C:\Users\Lenovo\Desktop\llmops-api\venv\lib\site-packages\flask\app.py", line 870, in full_dispatch_request
    rv = self.dispatch_request()
  File "C:\Users\Lenovo\Desktop\llmops-api\venv\lib\site-packages\flask\app.py", line 855, in dispatch_request
    return self.ensure_sync(self.view_functions[rule.endpoint])(**view_args)  # type: ignore[no-any-return]
  File "C:\Users\Lenovo\Desktop\llmops-api\internal\handler\app_handler.py", line 260, in ping
    from internal.core.agent.agents import FunctionCallAgent
  File "C:\Users\Lenovo\Desktop\llmops-api\internal\core\agent\agents\__init__.py", line 1, in <module>
    from .base_agent import BaseAgent
  File "C:\Users\Lenovo\Desktop\llmops-api\internal\core\agent\agents\base_agent.py", line 2, in <module>
    from internal.core.agent.entities.agent_entity import AgentConfig
  File "C:\Users\Lenovo\Desktop\llmops-api\internal\core\agent\entities\agent_entity.py", line 35, in <module>
    class AgentConfig(BaseModel):
  File "C:\Users\Lenovo\Desktop\llmops-api\venv\lib\site-packages\pydantic\v1\main.py", line 197, in __new__
    fields[ann_name] = ModelField.infer(
  File "C:\Users\Lenovo\Desktop\llmops-api\venv\lib\site-packages\pydantic\v1\fields.py", line 504, in infer
    return cls(
  File "C:\Users\Lenovo\Desktop\llmops-api\venv\lib\site-packages\pydantic\v1\fields.py", line 434, in __init__
    self.prepare()
  File "C:\Users\Lenovo\Desktop\llmops-api\venv\lib\site-packages\pydantic\v1\fields.py", line 555, in prepare
    self.populate_validators()
  File "C:\Users\Lenovo\Desktop\llmops-api\venv\lib\site-packages\pydantic\v1\fields.py", line 829, in populate_validators
    *(get_validators() if get_validators else list(find_validators(self.type_, self.model_config))),
  File "C:\Users\Lenovo\Desktop\llmops-api\venv\lib\site-packages\pydantic\v1\validators.py", line 768, in find_validators
    raise RuntimeError(f'no validator found for {type_}, see `arbitrary_types_allowed` in Config')
RuntimeError: no validator found for <class 'langchain_core.language_models.base.BaseLanguageModel'>, see `arbitrary_types_allowed` in Config
[2025-05-08 21:37:56,141.141] _internal.py -> _log line:97 [INFO]: 127.0.0.1 - - [08/May/2025 21:37:56] "[35m[1mGET /ping HTTP/1.1[0m" 500 -
[2025-05-08 21:38:04,533.533] _internal.py -> _log line:97 [INFO]:  * Detected change in 'C:\\Users\\Lenovo\\Desktop\\llmops-api\\internal\\core\\agent\\entities\\agent_entity.py', reloading
[2025-05-08 21:38:06,804.804] _internal.py -> _log line:97 [INFO]:  * Restarting with stat
[2025-05-08 21:38:34,276.276] _internal.py -> _log line:97 [WARNING]:  * Debugger is active!
[2025-05-08 21:38:34,292.292] _internal.py -> _log line:97 [INFO]:  * Debugger PIN: 674-688-502
[2025-05-08 21:39:05,017.017] _internal.py -> _log line:97 [INFO]:  * Detected change in 'C:\\Users\\Lenovo\\Desktop\\llmops-api\\internal\\core\\agent\\entities\\agent_entity.py', reloading
[2025-05-08 21:39:06,558.558] _internal.py -> _log line:97 [INFO]:  * Restarting with stat
[2025-05-08 21:39:34,101.101] _internal.py -> _log line:97 [WARNING]:  * Debugger is active!
[2025-05-08 21:39:34,232.232] _internal.py -> _log line:97 [INFO]:  * Debugger PIN: 674-688-502
[2025-05-08 21:39:45,541.541] _internal.py -> _log line:97 [INFO]: 127.0.0.1 - - [08/May/2025 21:39:45] "GET /ping HTTP/1.1" 200 -
[2025-05-08 21:39:56,058.058] _internal.py -> _log line:97 [INFO]:  * Detected change in 'C:\\Users\\Lenovo\\Desktop\\llmops-api\\internal\\core\\agent\\entities\\agent_entity.py', reloading
[2025-05-08 21:39:58,124.124] _internal.py -> _log line:97 [INFO]:  * Restarting with stat
[2025-05-08 21:40:26,183.183] _internal.py -> _log line:97 [WARNING]:  * Debugger is active!
[2025-05-08 21:40:26,194.194] _internal.py -> _log line:97 [INFO]:  * Debugger PIN: 674-688-502
[2025-05-08 21:41:47,877.877] _internal.py -> _log line:97 [INFO]:  * Detected change in 'C:\\Users\\Lenovo\\Desktop\\llmops-api\\internal\\core\\agent\\agents\\function_call_agent.py', reloading
[2025-05-08 21:41:49,413.413] _internal.py -> _log line:97 [INFO]:  * Restarting with stat
[2025-05-08 22:54:36,111.111] _internal.py -> _log line:97 [INFO]: [31m[1mWARNING: This is a development server. Do not use it in a production deployment. Use a production WSGI server instead.[0m
 * Running on http://127.0.0.1:5000
[2025-05-08 22:54:36,112.112] _internal.py -> _log line:97 [INFO]: [33mPress CTRL+C to quit[0m
[2025-05-08 22:54:36,118.118] _internal.py -> _log line:97 [INFO]:  * Restarting with stat
[2025-05-08 22:54:58,729.729] _internal.py -> _log line:97 [WARNING]:  * Debugger is active!
[2025-05-08 22:54:58,749.749] _internal.py -> _log line:97 [INFO]:  * Debugger PIN: 674-688-502
[2025-05-08 22:55:13,006.006] _internal.py -> _log line:97 [INFO]:  * Detected change in 'C:\\Users\\Lenovo\\Desktop\\llmops-api\\internal\\core\\agent\\agents\\function_call_agent.py', reloading
[2025-05-08 22:55:14,586.586] _internal.py -> _log line:97 [INFO]:  * Restarting with stat
[2025-05-08 22:55:37,097.097] _internal.py -> _log line:97 [WARNING]:  * Debugger is active!
[2025-05-08 22:55:37,112.112] _internal.py -> _log line:97 [INFO]:  * Debugger PIN: 674-688-502
[2025-05-08 22:55:39,318.318] http.py -> _register_error_handler line:54 [ERROR]: An error occurred: __init__() missing 1 required positional argument: 'agent_queue_manager'
Traceback (most recent call last):
  File "C:\Users\Lenovo\Desktop\llmops-api\venv\lib\site-packages\flask\app.py", line 870, in full_dispatch_request
    rv = self.dispatch_request()
  File "C:\Users\Lenovo\Desktop\llmops-api\venv\lib\site-packages\flask\app.py", line 855, in dispatch_request
    return self.ensure_sync(self.view_functions[rule.endpoint])(**view_args)  # type: ignore[no-any-return]
  File "C:\Users\Lenovo\Desktop\llmops-api\internal\handler\app_handler.py", line 264, in ping
    agent = FunctionCallAgent(AgentConfig(
TypeError: __init__() missing 1 required positional argument: 'agent_queue_manager'
[2025-05-08 22:55:39,346.346] _internal.py -> _log line:97 [INFO]: 127.0.0.1 - - [08/May/2025 22:55:39] "[35m[1mGET /ping HTTP/1.1[0m" 500 -
[2025-05-08 22:56:30,515.515] _internal.py -> _log line:97 [INFO]:  * Detected change in 'C:\\Users\\Lenovo\\Desktop\\llmops-api\\internal\\handler\\app_handler.py', reloading
[2025-05-08 22:56:32,002.002] _internal.py -> _log line:97 [INFO]:  * Restarting with stat
[2025-05-08 22:56:57,948.948] _internal.py -> _log line:97 [WARNING]:  * Debugger is active!
[2025-05-08 22:56:57,967.967] _internal.py -> _log line:97 [INFO]:  * Debugger PIN: 674-688-502
[2025-05-08 22:56:59,925.925] http.py -> _register_error_handler line:54 [ERROR]: An error occurred: __init__() missing 1 required positional argument: 'agent_queue_manager'
Traceback (most recent call last):
  File "C:\Users\Lenovo\Desktop\llmops-api\venv\lib\site-packages\flask\app.py", line 870, in full_dispatch_request
    rv = self.dispatch_request()
  File "C:\Users\Lenovo\Desktop\llmops-api\venv\lib\site-packages\flask\app.py", line 855, in dispatch_request
    return self.ensure_sync(self.view_functions[rule.endpoint])(**view_args)  # type: ignore[no-any-return]
  File "C:\Users\Lenovo\Desktop\llmops-api\internal\handler\app_handler.py", line 264, in ping
    agent = FunctionCallAgent(AgentConfig(
TypeError: __init__() missing 1 required positional argument: 'agent_queue_manager'
[2025-05-08 22:56:59,944.944] _internal.py -> _log line:97 [INFO]: 127.0.0.1 - - [08/May/2025 22:56:59] "[35m[1mGET /ping HTTP/1.1[0m" 500 -
[2025-05-08 22:57:47,117.117] _internal.py -> _log line:97 [INFO]:  * Detected change in 'C:\\Users\\Lenovo\\Desktop\\llmops-api\\internal\\core\\agent\\agents\\__init__.py', reloading
[2025-05-08 22:57:48,618.618] _internal.py -> _log line:97 [INFO]:  * Restarting with stat
[2025-05-08 22:58:21,468.468] _internal.py -> _log line:97 [WARNING]:  * Debugger is active!
[2025-05-08 22:58:21,481.481] _internal.py -> _log line:97 [INFO]:  * Debugger PIN: 674-688-502
[2025-05-08 22:58:31,418.418] _internal.py -> _log line:97 [INFO]:  * Detected change in 'C:\\Users\\Lenovo\\Desktop\\llmops-api\\internal\\core\\agent\\agents\\base_agent.py', reloading
[2025-05-08 22:58:33,483.483] _internal.py -> _log line:97 [INFO]:  * Restarting with stat
[2025-05-08 22:59:12,310.310] _internal.py -> _log line:97 [WARNING]:  * Debugger is active!
[2025-05-08 22:59:12,328.328] _internal.py -> _log line:97 [INFO]:  * Debugger PIN: 674-688-502
[2025-05-08 22:59:13,972.972] http.py -> _register_error_handler line:54 [ERROR]: An error occurred: __init__() missing 1 required positional argument: 'agent_queue_manager'
Traceback (most recent call last):
  File "C:\Users\Lenovo\Desktop\llmops-api\venv\lib\site-packages\flask\app.py", line 870, in full_dispatch_request
    rv = self.dispatch_request()
  File "C:\Users\Lenovo\Desktop\llmops-api\venv\lib\site-packages\flask\app.py", line 855, in dispatch_request
    return self.ensure_sync(self.view_functions[rule.endpoint])(**view_args)  # type: ignore[no-any-return]
  File "C:\Users\Lenovo\Desktop\llmops-api\internal\handler\app_handler.py", line 264, in ping
    agent = FunctionCallAgent(AgentConfig(
TypeError: __init__() missing 1 required positional argument: 'agent_queue_manager'
[2025-05-08 22:59:14,001.001] _internal.py -> _log line:97 [INFO]: 127.0.0.1 - - [08/May/2025 22:59:14] "[35m[1mGET /ping HTTP/1.1[0m" 500 -
[2025-05-08 23:00:35,735.735] _internal.py -> _log line:97 [INFO]:  * Detected change in 'C:\\Users\\Lenovo\\Desktop\\llmops-api\\internal\\handler\\app_handler.py', reloading
[2025-05-08 23:00:37,274.274] _internal.py -> _log line:97 [INFO]:  * Restarting with stat
[2025-05-08 23:01:01,776.776] _internal.py -> _log line:97 [WARNING]:  * Debugger is active!
[2025-05-08 23:01:01,793.793] _internal.py -> _log line:97 [INFO]:  * Debugger PIN: 674-688-502
[2025-05-08 23:01:03,494.494] http.py -> _register_error_handler line:54 [ERROR]: An error occurred: __init__() missing 1 required positional argument: 'agent_queue_manager'
Traceback (most recent call last):
  File "C:\Users\Lenovo\Desktop\llmops-api\venv\lib\site-packages\flask\app.py", line 870, in full_dispatch_request
    rv = self.dispatch_request()
  File "C:\Users\Lenovo\Desktop\llmops-api\venv\lib\site-packages\flask\app.py", line 855, in dispatch_request
    return self.ensure_sync(self.view_functions[rule.endpoint])(**view_args)  # type: ignore[no-any-return]
  File "C:\Users\Lenovo\Desktop\llmops-api\internal\handler\app_handler.py", line 264, in ping
    agent = FunctionCallAgent(AgentConfig(
TypeError: __init__() missing 1 required positional argument: 'agent_queue_manager'
[2025-05-08 23:01:03,511.511] _internal.py -> _log line:97 [INFO]: 127.0.0.1 - - [08/May/2025 23:01:03] "[35m[1mGET /ping HTTP/1.1[0m" 500 -
