[2025-06-04 14:55:59,310.310] _internal.py -> _log line:97 [INFO]: [31m[1mWARNING: This is a development server. Do not use it in a production deployment. Use a production WSGI server instead.[0m
 * Running on http://127.0.0.1:5000
[2025-06-04 14:55:59,311.311] _internal.py -> _log line:97 [INFO]: [33mPress CTRL+C to quit[0m
[2025-06-04 14:55:59,312.312] _internal.py -> _log line:97 [INFO]:  * Restarting with stat
[2025-06-04 14:56:04,505.505] _internal.py -> _log line:97 [WARNING]:  * Debugger is active!
[2025-06-04 14:56:04,509.509] _internal.py -> _log line:97 [INFO]:  * Debugger PIN: 674-688-502
[2025-06-04 14:56:04,765.765] base.py -> _exec_single_context line:1896 [INFO]: select pg_catalog.version()
[2025-06-04 14:56:04,765.765] base.py -> _exec_single_context line:1901 [INFO]: [raw sql] {}
[2025-06-04 14:56:04,768.768] base.py -> _exec_single_context line:1896 [INFO]: select current_schema()
[2025-06-04 14:56:04,768.768] base.py -> _exec_single_context line:1901 [INFO]: [raw sql] {}
[2025-06-04 14:56:04,769.769] base.py -> _exec_single_context line:1896 [INFO]: show standard_conforming_strings
[2025-06-04 14:56:04,770.770] base.py -> _exec_single_context line:1901 [INFO]: [raw sql] {}
[2025-06-04 14:56:04,770.770] base.py -> _begin_impl line:1097 [INFO]: BEGIN (implicit)
[2025-06-04 14:56:04,772.772] base.py -> _exec_single_context line:1896 [INFO]: SELECT account.id AS account_id, account.name AS account_name, account.email AS account_email, account.avatar AS account_avatar, account.password AS account_password, account.password_salt AS account_password_salt, account.last_login_at AS account_last_login_at, account.last_login_ip AS account_last_login_ip, account.updated_at AS account_updated_at, account.created_at AS account_created_at 
FROM account 
WHERE account.id = %(pk_1)s::UUID
[2025-06-04 14:56:04,772.772] base.py -> _exec_single_context line:1901 [INFO]: [generated in 0.00026s] {'pk_1': '46db30d1-3199-4e79-a0cd-abf12fa6858f'}
[2025-06-04 14:56:07,216.216] base.py -> _rollback_impl line:1123 [INFO]: ROLLBACK
[2025-06-04 14:56:07,216.216] _internal.py -> _log line:97 [INFO]: 127.0.0.1 - - [04/Jun/2025 14:56:07] "GET /ping HTTP/1.1" 200 -
[2025-06-04 22:00:02,496.496] _internal.py -> _log line:97 [INFO]: [31m[1mWARNING: This is a development server. Do not use it in a production deployment. Use a production WSGI server instead.[0m
 * Running on http://127.0.0.1:5000
[2025-06-04 22:00:02,496.496] _internal.py -> _log line:97 [INFO]: [33mPress CTRL+C to quit[0m
[2025-06-04 22:00:02,498.498] _internal.py -> _log line:97 [INFO]:  * Restarting with stat
[2025-06-04 22:00:07,566.566] _internal.py -> _log line:97 [WARNING]:  * Debugger is active!
[2025-06-04 22:00:07,569.569] _internal.py -> _log line:97 [INFO]:  * Debugger PIN: 674-688-502
[2025-06-04 22:00:38,866.866] _internal.py -> _log line:97 [INFO]:  * Detected change in 'C:\\Users\\Lenovo\\Desktop\\llmops-api\\internal\\handler\\app_handler.py', reloading
[2025-06-04 22:00:39,221.221] _internal.py -> _log line:97 [INFO]:  * Restarting with stat
[2025-06-04 22:00:44,390.390] _internal.py -> _log line:97 [WARNING]:  * Debugger is active!
[2025-06-04 22:00:44,393.393] _internal.py -> _log line:97 [INFO]:  * Debugger PIN: 674-688-502
[2025-06-04 22:00:49,274.274] base.py -> _exec_single_context line:1896 [INFO]: select pg_catalog.version()
[2025-06-04 22:00:49,274.274] base.py -> _exec_single_context line:1901 [INFO]: [raw sql] {}
[2025-06-04 22:00:49,277.277] base.py -> _exec_single_context line:1896 [INFO]: select current_schema()
[2025-06-04 22:00:49,278.278] base.py -> _exec_single_context line:1901 [INFO]: [raw sql] {}
[2025-06-04 22:00:49,280.280] base.py -> _exec_single_context line:1896 [INFO]: show standard_conforming_strings
[2025-06-04 22:00:49,280.280] base.py -> _exec_single_context line:1901 [INFO]: [raw sql] {}
[2025-06-04 22:00:49,281.281] base.py -> _begin_impl line:1097 [INFO]: BEGIN (implicit)
[2025-06-04 22:00:49,284.284] base.py -> _exec_single_context line:1896 [INFO]: SELECT account.id AS account_id, account.name AS account_name, account.email AS account_email, account.avatar AS account_avatar, account.password AS account_password, account.password_salt AS account_password_salt, account.last_login_at AS account_last_login_at, account.last_login_ip AS account_last_login_ip, account.updated_at AS account_updated_at, account.created_at AS account_created_at 
FROM account 
WHERE account.id = %(pk_1)s::UUID
[2025-06-04 22:00:49,285.285] base.py -> _exec_single_context line:1901 [INFO]: [generated in 0.00071s] {'pk_1': '46db30d1-3199-4e79-a0cd-abf12fa6858f'}
[2025-06-04 22:00:49,293.293] http.py -> _register_error_handler line:63 [ERROR]: An error occurred: 1 validation error for Chat
  Value error, Did not find dashscope_api_key, please add an environment variable `DASHSCOPE_API_KEY` which contains it, or pass `dashscope_api_key` as a named parameter. [type=value_error, input_value={'name': None, 'cache': N...alse, 'max_retries': 10}, input_type=dict]
    For further information visit https://errors.pydantic.dev/2.11/v/value_error
Traceback (most recent call last):
  File "C:\Users\Lenovo\Desktop\llmops-api\venv\lib\site-packages\flask\app.py", line 870, in full_dispatch_request
    rv = self.dispatch_request()
  File "C:\Users\Lenovo\Desktop\llmops-api\venv\lib\site-packages\flask\app.py", line 855, in dispatch_request
    return self.ensure_sync(self.view_functions[rule.endpoint])(**view_args)  # type: ignore[no-any-return]
  File "C:\Users\Lenovo\Desktop\llmops-api\venv\lib\site-packages\flask_login\utils.py", line 290, in decorated_view
    return current_app.ensure_sync(func)(*args, **kwargs)
  File "C:\Users\Lenovo\Desktop\llmops-api\internal\handler\app_handler.py", line 221, in ping
    llm = model_class(model="qwen-plus")
  File "C:\Users\Lenovo\Desktop\llmops-api\venv\lib\site-packages\langchain_core\load\serializable.py", line 125, in __init__
    super().__init__(*args, **kwargs)
  File "C:\Users\Lenovo\Desktop\llmops-api\venv\lib\site-packages\pydantic\main.py", line 253, in __init__
    validated_self = self.__pydantic_validator__.validate_python(data, self_instance=self)
pydantic_core._pydantic_core.ValidationError: 1 validation error for Chat
  Value error, Did not find dashscope_api_key, please add an environment variable `DASHSCOPE_API_KEY` which contains it, or pass `dashscope_api_key` as a named parameter. [type=value_error, input_value={'name': None, 'cache': N...alse, 'max_retries': 10}, input_type=dict]
    For further information visit https://errors.pydantic.dev/2.11/v/value_error
[2025-06-04 22:00:49,299.299] base.py -> _rollback_impl line:1123 [INFO]: ROLLBACK
[2025-06-04 22:00:49,333.333] _internal.py -> _log line:97 [INFO]: 127.0.0.1 - - [04/Jun/2025 22:00:49] "[35m[1mGET /ping HTTP/1.1[0m" 500 -
[2025-06-04 22:05:48,822.822] base.py -> _begin_impl line:1097 [INFO]: BEGIN (implicit)
[2025-06-04 22:05:48,822.822] base.py -> _exec_single_context line:1896 [INFO]: SELECT account.id AS account_id, account.name AS account_name, account.email AS account_email, account.avatar AS account_avatar, account.password AS account_password, account.password_salt AS account_password_salt, account.last_login_at AS account_last_login_at, account.last_login_ip AS account_last_login_ip, account.updated_at AS account_updated_at, account.created_at AS account_created_at 
FROM account 
WHERE account.id = %(pk_1)s::UUID
[2025-06-04 22:05:48,822.822] base.py -> _exec_single_context line:1901 [INFO]: [cached since 299.5s ago] {'pk_1': '46db30d1-3199-4e79-a0cd-abf12fa6858f'}
[2025-06-04 22:05:48,824.824] http.py -> _register_error_handler line:63 [ERROR]: An error occurred: 1 validation error for Chat
  Value error, Did not find dashscope_api_key, please add an environment variable `DASHSCOPE_API_KEY` which contains it, or pass `dashscope_api_key` as a named parameter. [type=value_error, input_value={'name': None, 'cache': N...alse, 'max_retries': 10}, input_type=dict]
    For further information visit https://errors.pydantic.dev/2.11/v/value_error
Traceback (most recent call last):
  File "C:\Users\Lenovo\Desktop\llmops-api\venv\lib\site-packages\flask\app.py", line 870, in full_dispatch_request
    rv = self.dispatch_request()
  File "C:\Users\Lenovo\Desktop\llmops-api\venv\lib\site-packages\flask\app.py", line 855, in dispatch_request
    return self.ensure_sync(self.view_functions[rule.endpoint])(**view_args)  # type: ignore[no-any-return]
  File "C:\Users\Lenovo\Desktop\llmops-api\venv\lib\site-packages\flask_login\utils.py", line 290, in decorated_view
    return current_app.ensure_sync(func)(*args, **kwargs)
  File "C:\Users\Lenovo\Desktop\llmops-api\internal\handler\app_handler.py", line 221, in ping
    llm = model_class(model="qwen-plus")
  File "C:\Users\Lenovo\Desktop\llmops-api\venv\lib\site-packages\langchain_core\load\serializable.py", line 125, in __init__
    super().__init__(*args, **kwargs)
  File "C:\Users\Lenovo\Desktop\llmops-api\venv\lib\site-packages\pydantic\main.py", line 253, in __init__
    validated_self = self.__pydantic_validator__.validate_python(data, self_instance=self)
pydantic_core._pydantic_core.ValidationError: 1 validation error for Chat
  Value error, Did not find dashscope_api_key, please add an environment variable `DASHSCOPE_API_KEY` which contains it, or pass `dashscope_api_key` as a named parameter. [type=value_error, input_value={'name': None, 'cache': N...alse, 'max_retries': 10}, input_type=dict]
    For further information visit https://errors.pydantic.dev/2.11/v/value_error
[2025-06-04 22:05:48,824.824] base.py -> _rollback_impl line:1123 [INFO]: ROLLBACK
[2025-06-04 22:05:48,833.833] _internal.py -> _log line:97 [INFO]: 127.0.0.1 - - [04/Jun/2025 22:05:48] "[35m[1mGET /ping HTTP/1.1[0m" 500 -
[2025-06-04 22:05:50,076.076] base.py -> _begin_impl line:1097 [INFO]: BEGIN (implicit)
[2025-06-04 22:05:50,077.077] base.py -> _exec_single_context line:1896 [INFO]: SELECT account.id AS account_id, account.name AS account_name, account.email AS account_email, account.avatar AS account_avatar, account.password AS account_password, account.password_salt AS account_password_salt, account.last_login_at AS account_last_login_at, account.last_login_ip AS account_last_login_ip, account.updated_at AS account_updated_at, account.created_at AS account_created_at 
FROM account 
WHERE account.id = %(pk_1)s::UUID
[2025-06-04 22:05:50,077.077] base.py -> _exec_single_context line:1901 [INFO]: [cached since 300.8s ago] {'pk_1': '46db30d1-3199-4e79-a0cd-abf12fa6858f'}
[2025-06-04 22:05:50,078.078] http.py -> _register_error_handler line:63 [ERROR]: An error occurred: 1 validation error for Chat
  Value error, Did not find dashscope_api_key, please add an environment variable `DASHSCOPE_API_KEY` which contains it, or pass `dashscope_api_key` as a named parameter. [type=value_error, input_value={'name': None, 'cache': N...alse, 'max_retries': 10}, input_type=dict]
    For further information visit https://errors.pydantic.dev/2.11/v/value_error
Traceback (most recent call last):
  File "C:\Users\Lenovo\Desktop\llmops-api\venv\lib\site-packages\flask\app.py", line 870, in full_dispatch_request
    rv = self.dispatch_request()
  File "C:\Users\Lenovo\Desktop\llmops-api\venv\lib\site-packages\flask\app.py", line 855, in dispatch_request
    return self.ensure_sync(self.view_functions[rule.endpoint])(**view_args)  # type: ignore[no-any-return]
  File "C:\Users\Lenovo\Desktop\llmops-api\venv\lib\site-packages\flask_login\utils.py", line 290, in decorated_view
    return current_app.ensure_sync(func)(*args, **kwargs)
  File "C:\Users\Lenovo\Desktop\llmops-api\internal\handler\app_handler.py", line 221, in ping
    llm = model_class(model="qwen-plus")
  File "C:\Users\Lenovo\Desktop\llmops-api\venv\lib\site-packages\langchain_core\load\serializable.py", line 125, in __init__
    super().__init__(*args, **kwargs)
  File "C:\Users\Lenovo\Desktop\llmops-api\venv\lib\site-packages\pydantic\main.py", line 253, in __init__
    validated_self = self.__pydantic_validator__.validate_python(data, self_instance=self)
pydantic_core._pydantic_core.ValidationError: 1 validation error for Chat
  Value error, Did not find dashscope_api_key, please add an environment variable `DASHSCOPE_API_KEY` which contains it, or pass `dashscope_api_key` as a named parameter. [type=value_error, input_value={'name': None, 'cache': N...alse, 'max_retries': 10}, input_type=dict]
    For further information visit https://errors.pydantic.dev/2.11/v/value_error
[2025-06-04 22:05:50,078.078] base.py -> _rollback_impl line:1123 [INFO]: ROLLBACK
[2025-06-04 22:05:50,087.087] _internal.py -> _log line:97 [INFO]: 127.0.0.1 - - [04/Jun/2025 22:05:50] "[35m[1mGET /ping HTTP/1.1[0m" 500 -
[2025-06-04 22:06:16,524.524] base.py -> _begin_impl line:1097 [INFO]: BEGIN (implicit)
[2025-06-04 22:06:16,524.524] base.py -> _exec_single_context line:1896 [INFO]: SELECT account.id AS account_id, account.name AS account_name, account.email AS account_email, account.avatar AS account_avatar, account.password AS account_password, account.password_salt AS account_password_salt, account.last_login_at AS account_last_login_at, account.last_login_ip AS account_last_login_ip, account.updated_at AS account_updated_at, account.created_at AS account_created_at 
FROM account 
WHERE account.id = %(pk_1)s::UUID
[2025-06-04 22:06:16,524.524] base.py -> _exec_single_context line:1901 [INFO]: [cached since 327.2s ago] {'pk_1': '46db30d1-3199-4e79-a0cd-abf12fa6858f'}
[2025-06-04 22:06:16,525.525] http.py -> _register_error_handler line:63 [ERROR]: An error occurred: 1 validation error for Chat
  Value error, Did not find dashscope_api_key, please add an environment variable `DASHSCOPE_API_KEY` which contains it, or pass `dashscope_api_key` as a named parameter. [type=value_error, input_value={'name': None, 'cache': N...alse, 'max_retries': 10}, input_type=dict]
    For further information visit https://errors.pydantic.dev/2.11/v/value_error
Traceback (most recent call last):
  File "C:\Users\Lenovo\Desktop\llmops-api\venv\lib\site-packages\flask\app.py", line 870, in full_dispatch_request
    rv = self.dispatch_request()
  File "C:\Users\Lenovo\Desktop\llmops-api\venv\lib\site-packages\flask\app.py", line 855, in dispatch_request
    return self.ensure_sync(self.view_functions[rule.endpoint])(**view_args)  # type: ignore[no-any-return]
  File "C:\Users\Lenovo\Desktop\llmops-api\venv\lib\site-packages\flask_login\utils.py", line 290, in decorated_view
    return current_app.ensure_sync(func)(*args, **kwargs)
  File "C:\Users\Lenovo\Desktop\llmops-api\internal\handler\app_handler.py", line 221, in ping
    llm = model_class(model="qwen-plus")
  File "C:\Users\Lenovo\Desktop\llmops-api\venv\lib\site-packages\langchain_core\load\serializable.py", line 125, in __init__
    super().__init__(*args, **kwargs)
  File "C:\Users\Lenovo\Desktop\llmops-api\venv\lib\site-packages\pydantic\main.py", line 253, in __init__
    validated_self = self.__pydantic_validator__.validate_python(data, self_instance=self)
pydantic_core._pydantic_core.ValidationError: 1 validation error for Chat
  Value error, Did not find dashscope_api_key, please add an environment variable `DASHSCOPE_API_KEY` which contains it, or pass `dashscope_api_key` as a named parameter. [type=value_error, input_value={'name': None, 'cache': N...alse, 'max_retries': 10}, input_type=dict]
    For further information visit https://errors.pydantic.dev/2.11/v/value_error
[2025-06-04 22:06:16,526.526] base.py -> _rollback_impl line:1123 [INFO]: ROLLBACK
[2025-06-04 22:06:16,534.534] _internal.py -> _log line:97 [INFO]: 127.0.0.1 - - [04/Jun/2025 22:06:16] "[35m[1mGET /ping HTTP/1.1[0m" 500 -
[2025-06-04 22:06:17,755.755] base.py -> _begin_impl line:1097 [INFO]: BEGIN (implicit)
[2025-06-04 22:06:17,756.756] base.py -> _exec_single_context line:1896 [INFO]: SELECT account.id AS account_id, account.name AS account_name, account.email AS account_email, account.avatar AS account_avatar, account.password AS account_password, account.password_salt AS account_password_salt, account.last_login_at AS account_last_login_at, account.last_login_ip AS account_last_login_ip, account.updated_at AS account_updated_at, account.created_at AS account_created_at 
FROM account 
WHERE account.id = %(pk_1)s::UUID
[2025-06-04 22:06:17,756.756] base.py -> _exec_single_context line:1901 [INFO]: [cached since 328.5s ago] {'pk_1': '46db30d1-3199-4e79-a0cd-abf12fa6858f'}
[2025-06-04 22:06:17,757.757] http.py -> _register_error_handler line:63 [ERROR]: An error occurred: 1 validation error for Chat
  Value error, Did not find dashscope_api_key, please add an environment variable `DASHSCOPE_API_KEY` which contains it, or pass `dashscope_api_key` as a named parameter. [type=value_error, input_value={'name': None, 'cache': N...alse, 'max_retries': 10}, input_type=dict]
    For further information visit https://errors.pydantic.dev/2.11/v/value_error
Traceback (most recent call last):
  File "C:\Users\Lenovo\Desktop\llmops-api\venv\lib\site-packages\flask\app.py", line 870, in full_dispatch_request
    rv = self.dispatch_request()
  File "C:\Users\Lenovo\Desktop\llmops-api\venv\lib\site-packages\flask\app.py", line 855, in dispatch_request
    return self.ensure_sync(self.view_functions[rule.endpoint])(**view_args)  # type: ignore[no-any-return]
  File "C:\Users\Lenovo\Desktop\llmops-api\venv\lib\site-packages\flask_login\utils.py", line 290, in decorated_view
    return current_app.ensure_sync(func)(*args, **kwargs)
  File "C:\Users\Lenovo\Desktop\llmops-api\internal\handler\app_handler.py", line 221, in ping
    llm = model_class(model="qwen-plus")
  File "C:\Users\Lenovo\Desktop\llmops-api\venv\lib\site-packages\langchain_core\load\serializable.py", line 125, in __init__
    super().__init__(*args, **kwargs)
  File "C:\Users\Lenovo\Desktop\llmops-api\venv\lib\site-packages\pydantic\main.py", line 253, in __init__
    validated_self = self.__pydantic_validator__.validate_python(data, self_instance=self)
pydantic_core._pydantic_core.ValidationError: 1 validation error for Chat
  Value error, Did not find dashscope_api_key, please add an environment variable `DASHSCOPE_API_KEY` which contains it, or pass `dashscope_api_key` as a named parameter. [type=value_error, input_value={'name': None, 'cache': N...alse, 'max_retries': 10}, input_type=dict]
    For further information visit https://errors.pydantic.dev/2.11/v/value_error
[2025-06-04 22:06:17,758.758] base.py -> _rollback_impl line:1123 [INFO]: ROLLBACK
[2025-06-04 22:06:17,767.767] _internal.py -> _log line:97 [INFO]: 127.0.0.1 - - [04/Jun/2025 22:06:17] "[35m[1mGET /ping HTTP/1.1[0m" 500 -
[2025-06-04 22:07:40,208.208] _internal.py -> _log line:97 [INFO]:  * Detected change in 'C:\\Users\\Lenovo\\Desktop\\llmops-api\\internal\\handler\\app_handler.py', reloading
[2025-06-04 22:07:40,556.556] _internal.py -> _log line:97 [INFO]:  * Restarting with stat
[2025-06-04 22:07:45,721.721] _internal.py -> _log line:97 [WARNING]:  * Debugger is active!
[2025-06-04 22:07:45,724.724] _internal.py -> _log line:97 [INFO]:  * Debugger PIN: 674-688-502
[2025-06-04 22:07:45,978.978] base.py -> _exec_single_context line:1896 [INFO]: select pg_catalog.version()
[2025-06-04 22:07:45,979.979] base.py -> _exec_single_context line:1901 [INFO]: [raw sql] {}
[2025-06-04 22:07:45,979.979] base.py -> _exec_single_context line:1896 [INFO]: select current_schema()
[2025-06-04 22:07:45,980.980] base.py -> _exec_single_context line:1901 [INFO]: [raw sql] {}
[2025-06-04 22:07:45,980.980] base.py -> _exec_single_context line:1896 [INFO]: show standard_conforming_strings
[2025-06-04 22:07:45,980.980] base.py -> _exec_single_context line:1901 [INFO]: [raw sql] {}
[2025-06-04 22:07:45,981.981] base.py -> _begin_impl line:1097 [INFO]: BEGIN (implicit)
[2025-06-04 22:07:45,982.982] base.py -> _exec_single_context line:1896 [INFO]: SELECT account.id AS account_id, account.name AS account_name, account.email AS account_email, account.avatar AS account_avatar, account.password AS account_password, account.password_salt AS account_password_salt, account.last_login_at AS account_last_login_at, account.last_login_ip AS account_last_login_ip, account.updated_at AS account_updated_at, account.created_at AS account_created_at 
FROM account 
WHERE account.id = %(pk_1)s::UUID
[2025-06-04 22:07:45,982.982] base.py -> _exec_single_context line:1901 [INFO]: [generated in 0.00028s] {'pk_1': '46db30d1-3199-4e79-a0cd-abf12fa6858f'}
[2025-06-04 22:07:45,984.984] http.py -> _register_error_handler line:63 [ERROR]: An error occurred: 
Traceback (most recent call last):
  File "C:\Users\Lenovo\Desktop\llmops-api\venv\lib\site-packages\flask\app.py", line 870, in full_dispatch_request
    rv = self.dispatch_request()
  File "C:\Users\Lenovo\Desktop\llmops-api\venv\lib\site-packages\flask\app.py", line 855, in dispatch_request
    return self.ensure_sync(self.view_functions[rule.endpoint])(**view_args)  # type: ignore[no-any-return]
  File "C:\Users\Lenovo\Desktop\llmops-api\venv\lib\site-packages\flask_login\utils.py", line 290, in decorated_view
    return current_app.ensure_sync(func)(*args, **kwargs)
  File "C:\Users\Lenovo\Desktop\llmops-api\internal\handler\app_handler.py", line 220, in ping
    model_class = self.language_model_manager.get_model_class_by_provider_and_model("deepseek", "deepseek-v3")
  File "C:\Users\Lenovo\Desktop\llmops-api\internal\core\language_model\language_model_manager.py", line 69, in get_model_class_by_provider_and_model
    provider = self.get_provider(provider_name)
  File "C:\Users\Lenovo\Desktop\llmops-api\internal\core\language_model\language_model_manager.py", line 45, in get_provider
    raise NotFoundException("该模型服务提供商不存在，请核实后重试")
internal.exception.exception.NotFoundException
[2025-06-04 22:07:45,988.988] base.py -> _rollback_impl line:1123 [INFO]: ROLLBACK
[2025-06-04 22:07:45,988.988] _internal.py -> _log line:97 [INFO]: 127.0.0.1 - - [04/Jun/2025 22:07:45] "GET /ping HTTP/1.1" 200 -
[2025-06-04 22:10:41,916.916] base.py -> _begin_impl line:1097 [INFO]: BEGIN (implicit)
[2025-06-04 22:10:41,916.916] base.py -> _exec_single_context line:1896 [INFO]: SELECT account.id AS account_id, account.name AS account_name, account.email AS account_email, account.avatar AS account_avatar, account.password AS account_password, account.password_salt AS account_password_salt, account.last_login_at AS account_last_login_at, account.last_login_ip AS account_last_login_ip, account.updated_at AS account_updated_at, account.created_at AS account_created_at 
FROM account 
WHERE account.id = %(pk_1)s::UUID
[2025-06-04 22:10:41,917.917] base.py -> _exec_single_context line:1901 [INFO]: [cached since 175.9s ago] {'pk_1': '46db30d1-3199-4e79-a0cd-abf12fa6858f'}
[2025-06-04 22:10:41,918.918] http.py -> _register_error_handler line:63 [ERROR]: An error occurred: 
Traceback (most recent call last):
  File "C:\Users\Lenovo\Desktop\llmops-api\venv\lib\site-packages\flask\app.py", line 870, in full_dispatch_request
    rv = self.dispatch_request()
  File "C:\Users\Lenovo\Desktop\llmops-api\venv\lib\site-packages\flask\app.py", line 855, in dispatch_request
    return self.ensure_sync(self.view_functions[rule.endpoint])(**view_args)  # type: ignore[no-any-return]
  File "C:\Users\Lenovo\Desktop\llmops-api\venv\lib\site-packages\flask_login\utils.py", line 290, in decorated_view
    return current_app.ensure_sync(func)(*args, **kwargs)
  File "C:\Users\Lenovo\Desktop\llmops-api\internal\handler\app_handler.py", line 220, in ping
    model_class = self.language_model_manager.get_model_class_by_provider_and_model("deepseek", "deepseek-v3")
  File "C:\Users\Lenovo\Desktop\llmops-api\internal\core\language_model\language_model_manager.py", line 69, in get_model_class_by_provider_and_model
    provider = self.get_provider(provider_name)
  File "C:\Users\Lenovo\Desktop\llmops-api\internal\core\language_model\language_model_manager.py", line 45, in get_provider
    raise NotFoundException("该模型服务提供商不存在，请核实后重试")
internal.exception.exception.NotFoundException
[2025-06-04 22:10:41,918.918] base.py -> _rollback_impl line:1123 [INFO]: ROLLBACK
[2025-06-04 22:10:41,919.919] _internal.py -> _log line:97 [INFO]: 127.0.0.1 - - [04/Jun/2025 22:10:41] "GET /ping HTTP/1.1" 200 -
[2025-06-04 22:10:44,115.115] base.py -> _begin_impl line:1097 [INFO]: BEGIN (implicit)
[2025-06-04 22:10:44,116.116] base.py -> _exec_single_context line:1896 [INFO]: SELECT account.id AS account_id, account.name AS account_name, account.email AS account_email, account.avatar AS account_avatar, account.password AS account_password, account.password_salt AS account_password_salt, account.last_login_at AS account_last_login_at, account.last_login_ip AS account_last_login_ip, account.updated_at AS account_updated_at, account.created_at AS account_created_at 
FROM account 
WHERE account.id = %(pk_1)s::UUID
[2025-06-04 22:10:44,117.117] base.py -> _exec_single_context line:1901 [INFO]: [cached since 178.1s ago] {'pk_1': '46db30d1-3199-4e79-a0cd-abf12fa6858f'}
[2025-06-04 22:10:44,118.118] http.py -> _register_error_handler line:63 [ERROR]: An error occurred: 
Traceback (most recent call last):
  File "C:\Users\Lenovo\Desktop\llmops-api\venv\lib\site-packages\flask\app.py", line 870, in full_dispatch_request
    rv = self.dispatch_request()
  File "C:\Users\Lenovo\Desktop\llmops-api\venv\lib\site-packages\flask\app.py", line 855, in dispatch_request
    return self.ensure_sync(self.view_functions[rule.endpoint])(**view_args)  # type: ignore[no-any-return]
  File "C:\Users\Lenovo\Desktop\llmops-api\venv\lib\site-packages\flask_login\utils.py", line 290, in decorated_view
    return current_app.ensure_sync(func)(*args, **kwargs)
  File "C:\Users\Lenovo\Desktop\llmops-api\internal\handler\app_handler.py", line 220, in ping
    model_class = self.language_model_manager.get_model_class_by_provider_and_model("deepseek", "deepseek-v3")
  File "C:\Users\Lenovo\Desktop\llmops-api\internal\core\language_model\language_model_manager.py", line 69, in get_model_class_by_provider_and_model
    provider = self.get_provider(provider_name)
  File "C:\Users\Lenovo\Desktop\llmops-api\internal\core\language_model\language_model_manager.py", line 45, in get_provider
    raise NotFoundException("该模型服务提供商不存在，请核实后重试")
internal.exception.exception.NotFoundException
[2025-06-04 22:10:44,119.119] base.py -> _rollback_impl line:1123 [INFO]: ROLLBACK
[2025-06-04 22:10:44,119.119] _internal.py -> _log line:97 [INFO]: 127.0.0.1 - - [04/Jun/2025 22:10:44] "GET /ping HTTP/1.1" 200 -
[2025-06-04 22:11:16,899.899] base.py -> _begin_impl line:1097 [INFO]: BEGIN (implicit)
[2025-06-04 22:11:16,899.899] base.py -> _exec_single_context line:1896 [INFO]: SELECT account.id AS account_id, account.name AS account_name, account.email AS account_email, account.avatar AS account_avatar, account.password AS account_password, account.password_salt AS account_password_salt, account.last_login_at AS account_last_login_at, account.last_login_ip AS account_last_login_ip, account.updated_at AS account_updated_at, account.created_at AS account_created_at 
FROM account 
WHERE account.id = %(pk_1)s::UUID
[2025-06-04 22:11:16,900.900] base.py -> _exec_single_context line:1901 [INFO]: [cached since 210.9s ago] {'pk_1': '46db30d1-3199-4e79-a0cd-abf12fa6858f'}
[2025-06-04 22:11:16,901.901] http.py -> _register_error_handler line:63 [ERROR]: An error occurred: 
Traceback (most recent call last):
  File "C:\Users\Lenovo\Desktop\llmops-api\venv\lib\site-packages\flask\app.py", line 870, in full_dispatch_request
    rv = self.dispatch_request()
  File "C:\Users\Lenovo\Desktop\llmops-api\venv\lib\site-packages\flask\app.py", line 855, in dispatch_request
    return self.ensure_sync(self.view_functions[rule.endpoint])(**view_args)  # type: ignore[no-any-return]
  File "C:\Users\Lenovo\Desktop\llmops-api\venv\lib\site-packages\flask_login\utils.py", line 290, in decorated_view
    return current_app.ensure_sync(func)(*args, **kwargs)
  File "C:\Users\Lenovo\Desktop\llmops-api\internal\handler\app_handler.py", line 220, in ping
    model_class = self.language_model_manager.get_model_class_by_provider_and_model("deepseek", "deepseek-v3")
  File "C:\Users\Lenovo\Desktop\llmops-api\internal\core\language_model\language_model_manager.py", line 69, in get_model_class_by_provider_and_model
    provider = self.get_provider(provider_name)
  File "C:\Users\Lenovo\Desktop\llmops-api\internal\core\language_model\language_model_manager.py", line 45, in get_provider
    raise NotFoundException("该模型服务提供商不存在，请核实后重试")
internal.exception.exception.NotFoundException
[2025-06-04 22:11:16,902.902] base.py -> _rollback_impl line:1123 [INFO]: ROLLBACK
[2025-06-04 22:11:16,902.902] _internal.py -> _log line:97 [INFO]: 127.0.0.1 - - [04/Jun/2025 22:11:16] "GET /ping HTTP/1.1" 200 -
[2025-06-04 22:11:17,811.811] base.py -> _begin_impl line:1097 [INFO]: BEGIN (implicit)
[2025-06-04 22:11:17,812.812] base.py -> _exec_single_context line:1896 [INFO]: SELECT account.id AS account_id, account.name AS account_name, account.email AS account_email, account.avatar AS account_avatar, account.password AS account_password, account.password_salt AS account_password_salt, account.last_login_at AS account_last_login_at, account.last_login_ip AS account_last_login_ip, account.updated_at AS account_updated_at, account.created_at AS account_created_at 
FROM account 
WHERE account.id = %(pk_1)s::UUID
[2025-06-04 22:11:17,812.812] base.py -> _exec_single_context line:1901 [INFO]: [cached since 211.8s ago] {'pk_1': '46db30d1-3199-4e79-a0cd-abf12fa6858f'}
[2025-06-04 22:11:17,814.814] http.py -> _register_error_handler line:63 [ERROR]: An error occurred: 
Traceback (most recent call last):
  File "C:\Users\Lenovo\Desktop\llmops-api\venv\lib\site-packages\flask\app.py", line 870, in full_dispatch_request
    rv = self.dispatch_request()
  File "C:\Users\Lenovo\Desktop\llmops-api\venv\lib\site-packages\flask\app.py", line 855, in dispatch_request
    return self.ensure_sync(self.view_functions[rule.endpoint])(**view_args)  # type: ignore[no-any-return]
  File "C:\Users\Lenovo\Desktop\llmops-api\venv\lib\site-packages\flask_login\utils.py", line 290, in decorated_view
    return current_app.ensure_sync(func)(*args, **kwargs)
  File "C:\Users\Lenovo\Desktop\llmops-api\internal\handler\app_handler.py", line 220, in ping
    model_class = self.language_model_manager.get_model_class_by_provider_and_model("deepseek", "deepseek-v3")
  File "C:\Users\Lenovo\Desktop\llmops-api\internal\core\language_model\language_model_manager.py", line 69, in get_model_class_by_provider_and_model
    provider = self.get_provider(provider_name)
  File "C:\Users\Lenovo\Desktop\llmops-api\internal\core\language_model\language_model_manager.py", line 45, in get_provider
    raise NotFoundException("该模型服务提供商不存在，请核实后重试")
internal.exception.exception.NotFoundException
[2025-06-04 22:11:17,816.816] base.py -> _rollback_impl line:1123 [INFO]: ROLLBACK
[2025-06-04 22:11:17,816.816] _internal.py -> _log line:97 [INFO]: 127.0.0.1 - - [04/Jun/2025 22:11:17] "GET /ping HTTP/1.1" 200 -
[2025-06-04 22:17:31,750.750] _internal.py -> _log line:97 [INFO]: [31m[1mWARNING: This is a development server. Do not use it in a production deployment. Use a production WSGI server instead.[0m
 * Running on http://127.0.0.1:5000
[2025-06-04 22:17:31,752.752] _internal.py -> _log line:97 [INFO]: [33mPress CTRL+C to quit[0m
[2025-06-04 22:17:31,753.753] _internal.py -> _log line:97 [INFO]:  * Restarting with stat
[2025-06-04 22:17:36,814.814] _internal.py -> _log line:97 [WARNING]:  * Debugger is active!
[2025-06-04 22:17:36,817.817] _internal.py -> _log line:97 [INFO]:  * Debugger PIN: 674-688-502
[2025-06-04 22:17:37,037.037] base.py -> _exec_single_context line:1896 [INFO]: select pg_catalog.version()
[2025-06-04 22:17:37,038.038] base.py -> _exec_single_context line:1901 [INFO]: [raw sql] {}
[2025-06-04 22:17:37,040.040] base.py -> _exec_single_context line:1896 [INFO]: select current_schema()
[2025-06-04 22:17:37,040.040] base.py -> _exec_single_context line:1901 [INFO]: [raw sql] {}
[2025-06-04 22:17:37,041.041] base.py -> _exec_single_context line:1896 [INFO]: show standard_conforming_strings
[2025-06-04 22:17:37,041.041] base.py -> _exec_single_context line:1901 [INFO]: [raw sql] {}
[2025-06-04 22:17:37,042.042] base.py -> _begin_impl line:1097 [INFO]: BEGIN (implicit)
[2025-06-04 22:17:37,043.043] base.py -> _exec_single_context line:1896 [INFO]: SELECT account.id AS account_id, account.name AS account_name, account.email AS account_email, account.avatar AS account_avatar, account.password AS account_password, account.password_salt AS account_password_salt, account.last_login_at AS account_last_login_at, account.last_login_ip AS account_last_login_ip, account.updated_at AS account_updated_at, account.created_at AS account_created_at 
FROM account 
WHERE account.id = %(pk_1)s::UUID
[2025-06-04 22:17:37,044.044] base.py -> _exec_single_context line:1901 [INFO]: [generated in 0.00026s] {'pk_1': '46db30d1-3199-4e79-a0cd-abf12fa6858f'}
[2025-06-04 22:17:37,800.800] http.py -> _register_error_handler line:63 [ERROR]: An error occurred: Error code: 400 - {'error': {'message': 'Model Not Exist', 'type': 'invalid_request_error', 'param': None, 'code': 'invalid_request_error'}}
Traceback (most recent call last):
  File "C:\Users\Lenovo\Desktop\llmops-api\venv\lib\site-packages\flask\app.py", line 870, in full_dispatch_request
    rv = self.dispatch_request()
  File "C:\Users\Lenovo\Desktop\llmops-api\venv\lib\site-packages\flask\app.py", line 855, in dispatch_request
    return self.ensure_sync(self.view_functions[rule.endpoint])(**view_args)  # type: ignore[no-any-return]
  File "C:\Users\Lenovo\Desktop\llmops-api\venv\lib\site-packages\flask_login\utils.py", line 290, in decorated_view
    return current_app.ensure_sync(func)(*args, **kwargs)
  File "C:\Users\Lenovo\Desktop\llmops-api\internal\handler\app_handler.py", line 223, in ping
    return success_message(llm.invoke("你好,你是?").content)
  File "C:\Users\Lenovo\Desktop\llmops-api\venv\lib\site-packages\langchain_core\language_models\chat_models.py", line 307, in invoke
    self.generate_prompt(
  File "C:\Users\Lenovo\Desktop\llmops-api\venv\lib\site-packages\langchain_core\language_models\chat_models.py", line 843, in generate_prompt
    return self.generate(prompt_messages, stop=stop, callbacks=callbacks, **kwargs)
  File "C:\Users\Lenovo\Desktop\llmops-api\venv\lib\site-packages\langchain_core\language_models\chat_models.py", line 683, in generate
    self._generate_with_cache(
  File "C:\Users\Lenovo\Desktop\llmops-api\venv\lib\site-packages\langchain_core\language_models\chat_models.py", line 908, in _generate_with_cache
    result = self._generate(
  File "C:\Users\Lenovo\Desktop\llmops-api\venv\lib\site-packages\langchain_deepseek\chat_models.py", line 296, in _generate
    return super()._generate(
  File "C:\Users\Lenovo\Desktop\llmops-api\venv\lib\site-packages\langchain_openai\chat_models\base.py", line 925, in _generate
    response = self.client.create(**payload)
  File "C:\Users\Lenovo\Desktop\llmops-api\venv\lib\site-packages\openai\_utils\_utils.py", line 279, in wrapper
    return func(*args, **kwargs)
  File "C:\Users\Lenovo\Desktop\llmops-api\venv\lib\site-packages\openai\resources\chat\completions\completions.py", line 914, in create
    return self._post(
  File "C:\Users\Lenovo\Desktop\llmops-api\venv\lib\site-packages\openai\_base_client.py", line 1242, in post
    return cast(ResponseT, self.request(cast_to, opts, stream=stream, stream_cls=stream_cls))
  File "C:\Users\Lenovo\Desktop\llmops-api\venv\lib\site-packages\openai\_base_client.py", line 919, in request
    return self._request(
  File "C:\Users\Lenovo\Desktop\llmops-api\venv\lib\site-packages\openai\_base_client.py", line 1023, in _request
    raise self._make_status_error_from_response(err.response) from None
openai.BadRequestError: Error code: 400 - {'error': {'message': 'Model Not Exist', 'type': 'invalid_request_error', 'param': None, 'code': 'invalid_request_error'}}
[2025-06-04 22:17:37,802.802] base.py -> _rollback_impl line:1123 [INFO]: ROLLBACK
[2025-06-04 22:17:37,816.816] _internal.py -> _log line:97 [INFO]: 127.0.0.1 - - [04/Jun/2025 22:17:37] "[35m[1mGET /ping HTTP/1.1[0m" 500 -
[2025-06-04 22:18:23,597.597] _internal.py -> _log line:97 [INFO]:  * Detected change in 'C:\\Users\\Lenovo\\Desktop\\llmops-api\\internal\\handler\\app_handler.py', reloading
[2025-06-04 22:18:24,040.040] _internal.py -> _log line:97 [INFO]:  * Restarting with stat
[2025-06-04 22:18:30,190.190] _internal.py -> _log line:97 [WARNING]:  * Debugger is active!
[2025-06-04 22:18:30,192.192] _internal.py -> _log line:97 [INFO]:  * Debugger PIN: 674-688-502
[2025-06-04 22:18:30,447.447] base.py -> _exec_single_context line:1896 [INFO]: select pg_catalog.version()
[2025-06-04 22:18:30,448.448] base.py -> _exec_single_context line:1901 [INFO]: [raw sql] {}
[2025-06-04 22:18:30,448.448] base.py -> _exec_single_context line:1896 [INFO]: select current_schema()
[2025-06-04 22:18:30,449.449] base.py -> _exec_single_context line:1901 [INFO]: [raw sql] {}
[2025-06-04 22:18:30,449.449] base.py -> _exec_single_context line:1896 [INFO]: show standard_conforming_strings
[2025-06-04 22:18:30,450.450] base.py -> _exec_single_context line:1901 [INFO]: [raw sql] {}
[2025-06-04 22:18:30,450.450] base.py -> _begin_impl line:1097 [INFO]: BEGIN (implicit)
[2025-06-04 22:18:30,452.452] base.py -> _exec_single_context line:1896 [INFO]: SELECT account.id AS account_id, account.name AS account_name, account.email AS account_email, account.avatar AS account_avatar, account.password AS account_password, account.password_salt AS account_password_salt, account.last_login_at AS account_last_login_at, account.last_login_ip AS account_last_login_ip, account.updated_at AS account_updated_at, account.created_at AS account_created_at 
FROM account 
WHERE account.id = %(pk_1)s::UUID
[2025-06-04 22:18:30,452.452] base.py -> _exec_single_context line:1901 [INFO]: [generated in 0.00050s] {'pk_1': '46db30d1-3199-4e79-a0cd-abf12fa6858f'}
[2025-06-04 22:18:30,941.941] http.py -> _register_error_handler line:63 [ERROR]: An error occurred: Error code: 400 - {'error': {'message': 'Model Not Exist', 'type': 'invalid_request_error', 'param': None, 'code': 'invalid_request_error'}}
Traceback (most recent call last):
  File "C:\Users\Lenovo\Desktop\llmops-api\venv\lib\site-packages\flask\app.py", line 870, in full_dispatch_request
    rv = self.dispatch_request()
  File "C:\Users\Lenovo\Desktop\llmops-api\venv\lib\site-packages\flask\app.py", line 855, in dispatch_request
    return self.ensure_sync(self.view_functions[rule.endpoint])(**view_args)  # type: ignore[no-any-return]
  File "C:\Users\Lenovo\Desktop\llmops-api\venv\lib\site-packages\flask_login\utils.py", line 290, in decorated_view
    return current_app.ensure_sync(func)(*args, **kwargs)
  File "C:\Users\Lenovo\Desktop\llmops-api\internal\handler\app_handler.py", line 223, in ping
    return success_message(llm.invoke("你好,你是?").content)
  File "C:\Users\Lenovo\Desktop\llmops-api\venv\lib\site-packages\langchain_core\language_models\chat_models.py", line 307, in invoke
    self.generate_prompt(
  File "C:\Users\Lenovo\Desktop\llmops-api\venv\lib\site-packages\langchain_core\language_models\chat_models.py", line 843, in generate_prompt
    return self.generate(prompt_messages, stop=stop, callbacks=callbacks, **kwargs)
  File "C:\Users\Lenovo\Desktop\llmops-api\venv\lib\site-packages\langchain_core\language_models\chat_models.py", line 683, in generate
    self._generate_with_cache(
  File "C:\Users\Lenovo\Desktop\llmops-api\venv\lib\site-packages\langchain_core\language_models\chat_models.py", line 908, in _generate_with_cache
    result = self._generate(
  File "C:\Users\Lenovo\Desktop\llmops-api\venv\lib\site-packages\langchain_deepseek\chat_models.py", line 296, in _generate
    return super()._generate(
  File "C:\Users\Lenovo\Desktop\llmops-api\venv\lib\site-packages\langchain_openai\chat_models\base.py", line 925, in _generate
    response = self.client.create(**payload)
  File "C:\Users\Lenovo\Desktop\llmops-api\venv\lib\site-packages\openai\_utils\_utils.py", line 279, in wrapper
    return func(*args, **kwargs)
  File "C:\Users\Lenovo\Desktop\llmops-api\venv\lib\site-packages\openai\resources\chat\completions\completions.py", line 914, in create
    return self._post(
  File "C:\Users\Lenovo\Desktop\llmops-api\venv\lib\site-packages\openai\_base_client.py", line 1242, in post
    return cast(ResponseT, self.request(cast_to, opts, stream=stream, stream_cls=stream_cls))
  File "C:\Users\Lenovo\Desktop\llmops-api\venv\lib\site-packages\openai\_base_client.py", line 919, in request
    return self._request(
  File "C:\Users\Lenovo\Desktop\llmops-api\venv\lib\site-packages\openai\_base_client.py", line 1023, in _request
    raise self._make_status_error_from_response(err.response) from None
openai.BadRequestError: Error code: 400 - {'error': {'message': 'Model Not Exist', 'type': 'invalid_request_error', 'param': None, 'code': 'invalid_request_error'}}
[2025-06-04 22:18:30,943.943] base.py -> _rollback_impl line:1123 [INFO]: ROLLBACK
[2025-06-04 22:18:30,957.957] _internal.py -> _log line:97 [INFO]: 127.0.0.1 - - [04/Jun/2025 22:18:30] "[35m[1mGET /ping HTTP/1.1[0m" 500 -
[2025-06-04 22:21:54,161.161] _internal.py -> _log line:97 [INFO]:  * Detected change in 'C:\\Users\\Lenovo\\Desktop\\llmops-api\\internal\\handler\\app_handler.py', reloading
[2025-06-04 22:21:54,513.513] _internal.py -> _log line:97 [INFO]:  * Restarting with stat
[2025-06-04 22:24:03,554.554] _internal.py -> _log line:97 [INFO]: [31m[1mWARNING: This is a development server. Do not use it in a production deployment. Use a production WSGI server instead.[0m
 * Running on http://127.0.0.1:5000
[2025-06-04 22:24:03,554.554] _internal.py -> _log line:97 [INFO]: [33mPress CTRL+C to quit[0m
[2025-06-04 22:24:03,554.554] _internal.py -> _log line:97 [INFO]:  * Restarting with stat
[2025-06-04 22:24:08,738.738] _internal.py -> _log line:97 [WARNING]:  * Debugger is active!
[2025-06-04 22:24:08,741.741] _internal.py -> _log line:97 [INFO]:  * Debugger PIN: 674-688-502
[2025-06-04 22:24:08,932.932] base.py -> _exec_single_context line:1896 [INFO]: select pg_catalog.version()
[2025-06-04 22:24:08,932.932] base.py -> _exec_single_context line:1901 [INFO]: [raw sql] {}
[2025-06-04 22:24:08,933.933] base.py -> _exec_single_context line:1896 [INFO]: select current_schema()
[2025-06-04 22:24:08,933.933] base.py -> _exec_single_context line:1901 [INFO]: [raw sql] {}
[2025-06-04 22:24:08,934.934] base.py -> _exec_single_context line:1896 [INFO]: show standard_conforming_strings
[2025-06-04 22:24:08,934.934] base.py -> _exec_single_context line:1901 [INFO]: [raw sql] {}
[2025-06-04 22:24:08,934.934] base.py -> _begin_impl line:1097 [INFO]: BEGIN (implicit)
[2025-06-04 22:24:08,936.936] base.py -> _exec_single_context line:1896 [INFO]: SELECT account.id AS account_id, account.name AS account_name, account.email AS account_email, account.avatar AS account_avatar, account.password AS account_password, account.password_salt AS account_password_salt, account.last_login_at AS account_last_login_at, account.last_login_ip AS account_last_login_ip, account.updated_at AS account_updated_at, account.created_at AS account_created_at 
FROM account 
WHERE account.id = %(pk_1)s::UUID
[2025-06-04 22:24:08,936.936] base.py -> _exec_single_context line:1901 [INFO]: [generated in 0.00033s] {'pk_1': '46db30d1-3199-4e79-a0cd-abf12fa6858f'}
[2025-06-04 22:24:18,564.564] base.py -> _rollback_impl line:1123 [INFO]: ROLLBACK
[2025-06-04 22:24:18,565.565] _internal.py -> _log line:97 [INFO]: 127.0.0.1 - - [04/Jun/2025 22:24:18] "GET /ping HTTP/1.1" 200 -
[2025-06-04 22:24:40,018.018] _internal.py -> _log line:97 [INFO]:  * Detected change in 'C:\\Users\\Lenovo\\Desktop\\llmops-api\\internal\\handler\\app_handler.py', reloading
[2025-06-04 22:24:40,331.331] _internal.py -> _log line:97 [INFO]:  * Restarting with stat
[2025-06-04 22:24:45,399.399] _internal.py -> _log line:97 [WARNING]:  * Debugger is active!
[2025-06-04 22:24:45,402.402] _internal.py -> _log line:97 [INFO]:  * Debugger PIN: 674-688-502
[2025-06-04 22:24:45,626.626] base.py -> _exec_single_context line:1896 [INFO]: select pg_catalog.version()
[2025-06-04 22:24:45,627.627] base.py -> _exec_single_context line:1901 [INFO]: [raw sql] {}
[2025-06-04 22:24:45,627.627] base.py -> _exec_single_context line:1896 [INFO]: select current_schema()
[2025-06-04 22:24:45,628.628] base.py -> _exec_single_context line:1901 [INFO]: [raw sql] {}
[2025-06-04 22:24:45,628.628] base.py -> _exec_single_context line:1896 [INFO]: show standard_conforming_strings
[2025-06-04 22:24:45,628.628] base.py -> _exec_single_context line:1901 [INFO]: [raw sql] {}
[2025-06-04 22:24:45,628.628] base.py -> _begin_impl line:1097 [INFO]: BEGIN (implicit)
[2025-06-04 22:24:45,630.630] base.py -> _exec_single_context line:1896 [INFO]: SELECT account.id AS account_id, account.name AS account_name, account.email AS account_email, account.avatar AS account_avatar, account.password AS account_password, account.password_salt AS account_password_salt, account.last_login_at AS account_last_login_at, account.last_login_ip AS account_last_login_ip, account.updated_at AS account_updated_at, account.created_at AS account_created_at 
FROM account 
WHERE account.id = %(pk_1)s::UUID
[2025-06-04 22:24:45,630.630] base.py -> _exec_single_context line:1901 [INFO]: [generated in 0.00031s] {'pk_1': '46db30d1-3199-4e79-a0cd-abf12fa6858f'}
[2025-06-04 22:24:46,495.495] base.py -> _rollback_impl line:1123 [INFO]: ROLLBACK
[2025-06-04 22:24:46,496.496] _internal.py -> _log line:97 [INFO]: 127.0.0.1 - - [04/Jun/2025 22:24:46] "GET /ping HTTP/1.1" 200 -
[2025-06-04 22:24:53,394.394] _internal.py -> _log line:97 [INFO]:  * Detected change in 'C:\\Users\\Lenovo\\Desktop\\llmops-api\\internal\\handler\\app_handler.py', reloading
[2025-06-04 22:24:53,736.736] _internal.py -> _log line:97 [INFO]:  * Restarting with stat
[2025-06-04 22:24:58,984.984] _internal.py -> _log line:97 [WARNING]:  * Debugger is active!
[2025-06-04 22:24:58,987.987] _internal.py -> _log line:97 [INFO]:  * Debugger PIN: 674-688-502
[2025-06-04 22:24:59,240.240] base.py -> _exec_single_context line:1896 [INFO]: select pg_catalog.version()
[2025-06-04 22:24:59,241.241] base.py -> _exec_single_context line:1901 [INFO]: [raw sql] {}
[2025-06-04 22:24:59,242.242] base.py -> _exec_single_context line:1896 [INFO]: select current_schema()
[2025-06-04 22:24:59,242.242] base.py -> _exec_single_context line:1901 [INFO]: [raw sql] {}
[2025-06-04 22:24:59,243.243] base.py -> _exec_single_context line:1896 [INFO]: show standard_conforming_strings
[2025-06-04 22:24:59,243.243] base.py -> _exec_single_context line:1901 [INFO]: [raw sql] {}
[2025-06-04 22:24:59,243.243] base.py -> _begin_impl line:1097 [INFO]: BEGIN (implicit)
[2025-06-04 22:24:59,245.245] base.py -> _exec_single_context line:1896 [INFO]: SELECT account.id AS account_id, account.name AS account_name, account.email AS account_email, account.avatar AS account_avatar, account.password AS account_password, account.password_salt AS account_password_salt, account.last_login_at AS account_last_login_at, account.last_login_ip AS account_last_login_ip, account.updated_at AS account_updated_at, account.created_at AS account_created_at 
FROM account 
WHERE account.id = %(pk_1)s::UUID
[2025-06-04 22:24:59,245.245] base.py -> _exec_single_context line:1901 [INFO]: [generated in 0.00026s] {'pk_1': '46db30d1-3199-4e79-a0cd-abf12fa6858f'}
[2025-06-04 22:25:02,906.906] base.py -> _rollback_impl line:1123 [INFO]: ROLLBACK
[2025-06-04 22:25:02,907.907] _internal.py -> _log line:97 [INFO]: 127.0.0.1 - - [04/Jun/2025 22:25:02] "GET /ping HTTP/1.1" 200 -
[2025-06-04 22:25:37,793.793] _internal.py -> _log line:97 [INFO]:  * Detected change in 'C:\\Users\\Lenovo\\Desktop\\llmops-api\\internal\\handler\\app_handler.py', reloading
[2025-06-04 22:25:38,208.208] _internal.py -> _log line:97 [INFO]:  * Restarting with stat
[2025-06-04 22:25:43,488.488] _internal.py -> _log line:97 [WARNING]:  * Debugger is active!
[2025-06-04 22:25:43,492.492] _internal.py -> _log line:97 [INFO]:  * Debugger PIN: 674-688-502
[2025-06-04 22:25:43,695.695] base.py -> _exec_single_context line:1896 [INFO]: select pg_catalog.version()
[2025-06-04 22:25:43,695.695] base.py -> _exec_single_context line:1901 [INFO]: [raw sql] {}
[2025-06-04 22:25:43,696.696] base.py -> _exec_single_context line:1896 [INFO]: select current_schema()
[2025-06-04 22:25:43,696.696] base.py -> _exec_single_context line:1901 [INFO]: [raw sql] {}
[2025-06-04 22:25:43,697.697] base.py -> _exec_single_context line:1896 [INFO]: show standard_conforming_strings
[2025-06-04 22:25:43,697.697] base.py -> _exec_single_context line:1901 [INFO]: [raw sql] {}
[2025-06-04 22:25:43,698.698] base.py -> _begin_impl line:1097 [INFO]: BEGIN (implicit)
[2025-06-04 22:25:43,699.699] base.py -> _exec_single_context line:1896 [INFO]: SELECT account.id AS account_id, account.name AS account_name, account.email AS account_email, account.avatar AS account_avatar, account.password AS account_password, account.password_salt AS account_password_salt, account.last_login_at AS account_last_login_at, account.last_login_ip AS account_last_login_ip, account.updated_at AS account_updated_at, account.created_at AS account_created_at 
FROM account 
WHERE account.id = %(pk_1)s::UUID
[2025-06-04 22:25:43,700.700] base.py -> _exec_single_context line:1901 [INFO]: [generated in 0.00031s] {'pk_1': '46db30d1-3199-4e79-a0cd-abf12fa6858f'}
[2025-06-04 22:25:45,301.301] base.py -> _rollback_impl line:1123 [INFO]: ROLLBACK
[2025-06-04 22:25:45,302.302] _internal.py -> _log line:97 [INFO]: 127.0.0.1 - - [04/Jun/2025 22:25:45] "GET /ping HTTP/1.1" 200 -
[2025-06-04 22:26:21,607.607] _internal.py -> _log line:97 [INFO]:  * Detected change in 'C:\\Users\\Lenovo\\Desktop\\llmops-api\\internal\\handler\\app_handler.py', reloading
[2025-06-04 22:26:21,955.955] _internal.py -> _log line:97 [INFO]:  * Restarting with stat
[2025-06-04 22:26:27,182.182] _internal.py -> _log line:97 [WARNING]:  * Debugger is active!
[2025-06-04 22:26:27,184.184] _internal.py -> _log line:97 [INFO]:  * Debugger PIN: 674-688-502
[2025-06-04 22:26:27,390.390] base.py -> _exec_single_context line:1896 [INFO]: select pg_catalog.version()
[2025-06-04 22:26:27,390.390] base.py -> _exec_single_context line:1901 [INFO]: [raw sql] {}
[2025-06-04 22:26:27,391.391] base.py -> _exec_single_context line:1896 [INFO]: select current_schema()
[2025-06-04 22:26:27,391.391] base.py -> _exec_single_context line:1901 [INFO]: [raw sql] {}
[2025-06-04 22:26:27,392.392] base.py -> _exec_single_context line:1896 [INFO]: show standard_conforming_strings
[2025-06-04 22:26:27,392.392] base.py -> _exec_single_context line:1901 [INFO]: [raw sql] {}
[2025-06-04 22:26:27,393.393] base.py -> _begin_impl line:1097 [INFO]: BEGIN (implicit)
[2025-06-04 22:26:27,394.394] base.py -> _exec_single_context line:1896 [INFO]: SELECT account.id AS account_id, account.name AS account_name, account.email AS account_email, account.avatar AS account_avatar, account.password AS account_password, account.password_salt AS account_password_salt, account.last_login_at AS account_last_login_at, account.last_login_ip AS account_last_login_ip, account.updated_at AS account_updated_at, account.created_at AS account_created_at 
FROM account 
WHERE account.id = %(pk_1)s::UUID
[2025-06-04 22:26:27,395.395] base.py -> _exec_single_context line:1901 [INFO]: [generated in 0.00048s] {'pk_1': '46db30d1-3199-4e79-a0cd-abf12fa6858f'}
[2025-06-04 22:26:27,397.397] http.py -> _register_error_handler line:63 [ERROR]: An error occurred: 
Traceback (most recent call last):
  File "C:\Users\Lenovo\Desktop\llmops-api\venv\lib\site-packages\flask\app.py", line 870, in full_dispatch_request
    rv = self.dispatch_request()
  File "C:\Users\Lenovo\Desktop\llmops-api\venv\lib\site-packages\flask\app.py", line 855, in dispatch_request
    return self.ensure_sync(self.view_functions[rule.endpoint])(**view_args)  # type: ignore[no-any-return]
  File "C:\Users\Lenovo\Desktop\llmops-api\venv\lib\site-packages\flask_login\utils.py", line 290, in decorated_view
    return current_app.ensure_sync(func)(*args, **kwargs)
  File "C:\Users\Lenovo\Desktop\llmops-api\internal\handler\app_handler.py", line 220, in ping
    model_class = self.language_model_manager.get_model_class_by_provider_and_model("openai", "openai-4o-mini")
  File "C:\Users\Lenovo\Desktop\llmops-api\internal\core\language_model\language_model_manager.py", line 72, in get_model_class_by_provider_and_model
    model_entity = provider.get_model_entity(model_name)
  File "C:\Users\Lenovo\Desktop\llmops-api\internal\core\language_model\entities\provider_entity.py", line 95, in get_model_entity
    raise NotFoundException("该模型实体不存在，请核实后重试")
internal.exception.exception.NotFoundException
[2025-06-04 22:26:27,402.402] base.py -> _rollback_impl line:1123 [INFO]: ROLLBACK
[2025-06-04 22:26:27,403.403] _internal.py -> _log line:97 [INFO]: 127.0.0.1 - - [04/Jun/2025 22:26:27] "GET /ping HTTP/1.1" 200 -
[2025-06-04 22:26:45,573.573] _internal.py -> _log line:97 [INFO]:  * Detected change in 'C:\\Users\\Lenovo\\Desktop\\llmops-api\\internal\\handler\\app_handler.py', reloading
[2025-06-04 22:26:45,927.927] _internal.py -> _log line:97 [INFO]:  * Restarting with stat
[2025-06-04 22:26:51,276.276] _internal.py -> _log line:97 [WARNING]:  * Debugger is active!
[2025-06-04 22:26:51,278.278] _internal.py -> _log line:97 [INFO]:  * Debugger PIN: 674-688-502
[2025-06-04 22:26:51,513.513] base.py -> _exec_single_context line:1896 [INFO]: select pg_catalog.version()
[2025-06-04 22:26:51,514.514] base.py -> _exec_single_context line:1901 [INFO]: [raw sql] {}
[2025-06-04 22:26:51,515.515] base.py -> _exec_single_context line:1896 [INFO]: select current_schema()
[2025-06-04 22:26:51,515.515] base.py -> _exec_single_context line:1901 [INFO]: [raw sql] {}
[2025-06-04 22:26:51,515.515] base.py -> _exec_single_context line:1896 [INFO]: show standard_conforming_strings
[2025-06-04 22:26:51,516.516] base.py -> _exec_single_context line:1901 [INFO]: [raw sql] {}
[2025-06-04 22:26:51,516.516] base.py -> _begin_impl line:1097 [INFO]: BEGIN (implicit)
[2025-06-04 22:26:51,518.518] base.py -> _exec_single_context line:1896 [INFO]: SELECT account.id AS account_id, account.name AS account_name, account.email AS account_email, account.avatar AS account_avatar, account.password AS account_password, account.password_salt AS account_password_salt, account.last_login_at AS account_last_login_at, account.last_login_ip AS account_last_login_ip, account.updated_at AS account_updated_at, account.created_at AS account_created_at 
FROM account 
WHERE account.id = %(pk_1)s::UUID
[2025-06-04 22:26:51,518.518] base.py -> _exec_single_context line:1901 [INFO]: [generated in 0.00029s] {'pk_1': '46db30d1-3199-4e79-a0cd-abf12fa6858f'}
[2025-06-04 22:26:59,717.717] base.py -> _rollback_impl line:1123 [INFO]: ROLLBACK
[2025-06-04 22:26:59,718.718] _internal.py -> _log line:97 [INFO]: 127.0.0.1 - - [04/Jun/2025 22:26:59] "GET /ping HTTP/1.1" 200 -
[2025-06-04 22:27:11,844.844] _internal.py -> _log line:97 [INFO]:  * Detected change in 'C:\\Users\\Lenovo\\Desktop\\llmops-api\\internal\\handler\\app_handler.py', reloading
[2025-06-04 22:27:12,288.288] _internal.py -> _log line:97 [INFO]:  * Restarting with stat
[2025-06-04 22:27:17,585.585] _internal.py -> _log line:97 [WARNING]:  * Debugger is active!
[2025-06-04 22:27:17,588.588] _internal.py -> _log line:97 [INFO]:  * Debugger PIN: 674-688-502
[2025-06-04 22:27:17,915.915] base.py -> _exec_single_context line:1896 [INFO]: select pg_catalog.version()
[2025-06-04 22:27:17,915.915] base.py -> _exec_single_context line:1901 [INFO]: [raw sql] {}
[2025-06-04 22:27:17,916.916] base.py -> _exec_single_context line:1896 [INFO]: select current_schema()
[2025-06-04 22:27:17,916.916] base.py -> _exec_single_context line:1901 [INFO]: [raw sql] {}
[2025-06-04 22:27:17,917.917] base.py -> _exec_single_context line:1896 [INFO]: show standard_conforming_strings
[2025-06-04 22:27:17,917.917] base.py -> _exec_single_context line:1901 [INFO]: [raw sql] {}
[2025-06-04 22:27:17,918.918] base.py -> _begin_impl line:1097 [INFO]: BEGIN (implicit)
[2025-06-04 22:27:17,919.919] base.py -> _exec_single_context line:1896 [INFO]: SELECT account.id AS account_id, account.name AS account_name, account.email AS account_email, account.avatar AS account_avatar, account.password AS account_password, account.password_salt AS account_password_salt, account.last_login_at AS account_last_login_at, account.last_login_ip AS account_last_login_ip, account.updated_at AS account_updated_at, account.created_at AS account_created_at 
FROM account 
WHERE account.id = %(pk_1)s::UUID
[2025-06-04 22:27:17,919.919] base.py -> _exec_single_context line:1901 [INFO]: [generated in 0.00025s] {'pk_1': '46db30d1-3199-4e79-a0cd-abf12fa6858f'}
[2025-06-04 22:27:23,410.410] base.py -> _rollback_impl line:1123 [INFO]: ROLLBACK
[2025-06-04 22:27:23,410.410] _internal.py -> _log line:97 [INFO]: 127.0.0.1 - - [04/Jun/2025 22:27:23] "GET /ping HTTP/1.1" 200 -
[2025-06-04 22:27:42,606.606] _internal.py -> _log line:97 [INFO]:  * Detected change in 'C:\\Users\\Lenovo\\Desktop\\llmops-api\\internal\\handler\\app_handler.py', reloading
[2025-06-04 22:27:43,023.023] _internal.py -> _log line:97 [INFO]:  * Restarting with stat
[2025-06-04 22:27:48,326.326] _internal.py -> _log line:97 [WARNING]:  * Debugger is active!
[2025-06-04 22:27:48,328.328] _internal.py -> _log line:97 [INFO]:  * Debugger PIN: 674-688-502
[2025-06-04 22:27:48,526.526] base.py -> _exec_single_context line:1896 [INFO]: select pg_catalog.version()
[2025-06-04 22:27:48,526.526] base.py -> _exec_single_context line:1901 [INFO]: [raw sql] {}
[2025-06-04 22:27:48,527.527] base.py -> _exec_single_context line:1896 [INFO]: select current_schema()
[2025-06-04 22:27:48,527.527] base.py -> _exec_single_context line:1901 [INFO]: [raw sql] {}
[2025-06-04 22:27:48,528.528] base.py -> _exec_single_context line:1896 [INFO]: show standard_conforming_strings
[2025-06-04 22:27:48,528.528] base.py -> _exec_single_context line:1901 [INFO]: [raw sql] {}
[2025-06-04 22:27:48,529.529] base.py -> _begin_impl line:1097 [INFO]: BEGIN (implicit)
[2025-06-04 22:27:48,530.530] base.py -> _exec_single_context line:1896 [INFO]: SELECT account.id AS account_id, account.name AS account_name, account.email AS account_email, account.avatar AS account_avatar, account.password AS account_password, account.password_salt AS account_password_salt, account.last_login_at AS account_last_login_at, account.last_login_ip AS account_last_login_ip, account.updated_at AS account_updated_at, account.created_at AS account_created_at 
FROM account 
WHERE account.id = %(pk_1)s::UUID
[2025-06-04 22:27:48,531.531] base.py -> _exec_single_context line:1901 [INFO]: [generated in 0.00033s] {'pk_1': '46db30d1-3199-4e79-a0cd-abf12fa6858f'}
[2025-06-04 22:27:55,237.237] base.py -> _rollback_impl line:1123 [INFO]: ROLLBACK
[2025-06-04 22:27:55,238.238] _internal.py -> _log line:97 [INFO]: 127.0.0.1 - - [04/Jun/2025 22:27:55] "GET /ping HTTP/1.1" 200 -
[2025-06-04 22:29:20,263.263] _internal.py -> _log line:97 [INFO]: [31m[1mWARNING: This is a development server. Do not use it in a production deployment. Use a production WSGI server instead.[0m
 * Running on http://127.0.0.1:5000
[2025-06-04 22:29:20,263.263] _internal.py -> _log line:97 [INFO]: [33mPress CTRL+C to quit[0m
[2025-06-04 22:29:20,264.264] _internal.py -> _log line:97 [INFO]:  * Restarting with stat
[2025-06-04 22:29:25,349.349] _internal.py -> _log line:97 [WARNING]:  * Debugger is active!
[2025-06-04 22:29:25,352.352] _internal.py -> _log line:97 [INFO]:  * Debugger PIN: 674-688-502
[2025-06-04 22:31:07,343.343] _internal.py -> _log line:97 [INFO]:  * Detected change in 'C:\\Users\\Lenovo\\Desktop\\llmops-api\\internal\\handler\\app_handler.py', reloading
[2025-06-04 22:31:07,702.702] _internal.py -> _log line:97 [INFO]:  * Restarting with stat
[2025-06-04 22:31:12,718.718] _internal.py -> _log line:97 [WARNING]:  * Debugger is active!
[2025-06-04 22:31:12,721.721] _internal.py -> _log line:97 [INFO]:  * Debugger PIN: 674-688-502
[2025-06-04 22:32:02,074.074] base.py -> _exec_single_context line:1896 [INFO]: select pg_catalog.version()
[2025-06-04 22:32:02,074.074] base.py -> _exec_single_context line:1901 [INFO]: [raw sql] {}
[2025-06-04 22:32:02,075.075] base.py -> _exec_single_context line:1896 [INFO]: select current_schema()
[2025-06-04 22:32:02,076.076] base.py -> _exec_single_context line:1901 [INFO]: [raw sql] {}
[2025-06-04 22:32:02,077.077] base.py -> _exec_single_context line:1896 [INFO]: show standard_conforming_strings
[2025-06-04 22:32:02,077.077] base.py -> _exec_single_context line:1901 [INFO]: [raw sql] {}
[2025-06-04 22:32:02,078.078] base.py -> _begin_impl line:1097 [INFO]: BEGIN (implicit)
[2025-06-04 22:32:02,080.080] base.py -> _exec_single_context line:1896 [INFO]: SELECT account.id AS account_id, account.name AS account_name, account.email AS account_email, account.avatar AS account_avatar, account.password AS account_password, account.password_salt AS account_password_salt, account.last_login_at AS account_last_login_at, account.last_login_ip AS account_last_login_ip, account.updated_at AS account_updated_at, account.created_at AS account_created_at 
FROM account 
WHERE account.id = %(pk_1)s::UUID
[2025-06-04 22:32:02,081.081] base.py -> _exec_single_context line:1901 [INFO]: [generated in 0.00043s] {'pk_1': '46db30d1-3199-4e79-a0cd-abf12fa6858f'}
[2025-06-04 22:32:02,660.660] utils.py -> __init__ line:128 [INFO]: no event loop in thread `Thread-3`, async feature won't be available. Please make sure the object is initialized in the thread with event loop.
[2025-06-04 22:32:02,660.660] oauth.py -> refresh_access_token line:228 [INFO]: trying to refresh access_token for ak `o9a9XO***`
[2025-06-04 22:32:02,799.799] oauth.py -> refresh_access_token line:243 [INFO]: sucessfully refresh access_token
[2025-06-04 22:32:07,558.558] base.py -> _rollback_impl line:1123 [INFO]: ROLLBACK
[2025-06-04 22:32:07,559.559] _internal.py -> _log line:97 [INFO]: 127.0.0.1 - - [04/Jun/2025 22:32:07] "GET /ping HTTP/1.1" 200 -
