[2025-05-28 12:02:40,234.234] _internal.py -> _log line:97 [INFO]: [31m[1mWARNING: This is a development server. Do not use it in a production deployment. Use a production WSGI server instead.[0m
 * Running on http://127.0.0.1:5000
[2025-05-28 12:02:40,235.235] _internal.py -> _log line:97 [INFO]: [33mPress CTRL+C to quit[0m
[2025-05-28 12:02:40,242.242] _internal.py -> _log line:97 [INFO]:  * Restarting with stat
[2025-05-28 12:03:33,943.943] _internal.py -> _log line:97 [WARNING]:  * Debugger is active!
[2025-05-28 12:03:33,962.962] _internal.py -> _log line:97 [INFO]:  * Debugger PIN: 674-688-502
[2025-05-28 12:04:15,277.277] _internal.py -> _log line:97 [INFO]:  * Detected change in 'C:\\Users\\Lenovo\\Desktop\\llmops-api\\internal\\core\\workflow\\entities\\variable_entity.py', reloading
[2025-05-28 12:04:17,583.583] _internal.py -> _log line:97 [INFO]:  * Restarting with stat
[2025-05-28 12:05:19,312.312] _internal.py -> _log line:97 [WARNING]:  * Debugger is active!
[2025-05-28 12:05:19,382.382] _internal.py -> _log line:97 [INFO]:  * Debugger PIN: 674-688-502
[2025-05-28 12:06:13,474.474] _internal.py -> _log line:97 [INFO]:  * Detected change in 'C:\\Users\\Lenovo\\Desktop\\llmops-api\\internal\\core\\workflow\\entities\\variable_entity.py', reloading
[2025-05-28 12:06:16,787.787] _internal.py -> _log line:97 [INFO]:  * Restarting with stat
[2025-05-28 12:07:09,804.804] _internal.py -> _log line:97 [WARNING]:  * Debugger is active!
[2025-05-28 12:07:09,815.815] _internal.py -> _log line:97 [INFO]:  * Debugger PIN: 674-688-502
[2025-05-28 12:07:11,445.445] base.py -> _exec_single_context line:1896 [INFO]: select pg_catalog.version()
[2025-05-28 12:07:11,446.446] base.py -> _exec_single_context line:1901 [INFO]: [raw sql] {}
[2025-05-28 12:07:11,451.451] base.py -> _exec_single_context line:1896 [INFO]: select current_schema()
[2025-05-28 12:07:11,451.451] base.py -> _exec_single_context line:1901 [INFO]: [raw sql] {}
[2025-05-28 12:07:11,453.453] base.py -> _exec_single_context line:1896 [INFO]: show standard_conforming_strings
[2025-05-28 12:07:11,453.453] base.py -> _exec_single_context line:1901 [INFO]: [raw sql] {}
[2025-05-28 12:07:11,454.454] base.py -> _begin_impl line:1097 [INFO]: BEGIN (implicit)
[2025-05-28 12:07:11,465.465] base.py -> _exec_single_context line:1896 [INFO]: SELECT account.id AS account_id, account.name AS account_name, account.email AS account_email, account.avatar AS account_avatar, account.password AS account_password, account.password_salt AS account_password_salt, account.last_login_at AS account_last_login_at, account.last_login_ip AS account_last_login_ip, account.updated_at AS account_updated_at, account.created_at AS account_created_at 
FROM account 
WHERE account.id = %(pk_1)s::UUID
[2025-05-28 12:07:11,467.467] base.py -> _exec_single_context line:1901 [INFO]: [generated in 0.00078s] {'pk_1': '46db30d1-3199-4e79-a0cd-abf12fa6858f'}
[2025-05-28 12:07:11,636.636] http.py -> _register_error_handler line:63 [ERROR]: An error occurred: 'dict' object has no attribute 'name'
Traceback (most recent call last):
  File "C:\Users\Lenovo\Desktop\llmops-api\venv\lib\site-packages\flask\app.py", line 870, in full_dispatch_request
    rv = self.dispatch_request()
  File "C:\Users\Lenovo\Desktop\llmops-api\venv\lib\site-packages\flask\app.py", line 855, in dispatch_request
    return self.ensure_sync(self.view_functions[rule.endpoint])(**view_args)  # type: ignore[no-any-return]
  File "C:\Users\Lenovo\Desktop\llmops-api\venv\lib\site-packages\flask_login\utils.py", line 290, in decorated_view
    return current_app.ensure_sync(func)(*args, **kwargs)
  File "C:\Users\Lenovo\Desktop\llmops-api\internal\handler\app_handler.py", line 628, in ping
    workflow = Workflow(workflow_config=WorkflowConfig(
  File "C:\Users\Lenovo\Desktop\llmops-api\internal\core\workflow\workflow.py", line 33, in __init__
    args_schema=self._build_args_schema(workflow_config),
  File "C:\Users\Lenovo\Desktop\llmops-api\internal\core\workflow\workflow.py", line 53, in _build_args_schema
    field_name = input.name
AttributeError: 'dict' object has no attribute 'name'
[2025-05-28 12:07:11,647.647] base.py -> _rollback_impl line:1123 [INFO]: ROLLBACK
[2025-05-28 12:07:11,665.665] _internal.py -> _log line:97 [INFO]: 127.0.0.1 - - [28/May/2025 12:07:11] "[35m[1mGET /ping HTTP/1.1[0m" 500 -
